/*
*** MADE BY MRPONYCAPTAIN'S .SCHEMATIC TO .JAVA CONVERTING TOOL v2.0 ***
*/

package com.ktreus.minecraftrealms.structures;

import java.util.Random;

import net.minecraft.block.Block;
import net.minecraft.init.Blocks;
import net.minecraft.world.World;
import net.minecraft.world.chunk.IChunkProvider;
import net.minecraft.world.gen.feature.WorldGenerator;
import cpw.mods.fml.common.IWorldGenerator;

public class MRCampTest extends WorldGenerator
{

	protected Block[] getValidSpawnBlocks() {
		return new Block[] {
			Blocks.grass,
			Blocks.sand
		};
	}

	public boolean locationIsValidSpawn(World world, int i, int j, int k){
		int distanceToAir = 0;
		Block check = world.getBlock(i, j, k);

		while (check != Blocks.air){
			if (distanceToAir > 3){
				return false;
			}

			distanceToAir++;
			check = world.getBlock(i, j + distanceToAir, k);
		}

		j += distanceToAir - 1;

		Block block = world.getBlock(i, j, k);
		Block blockAbove = world.getBlock(i, j+1, k);
		Block blockBelow = world.getBlock(i, j-1, k);
		
		for (Block x : getValidSpawnBlocks()){
			if (blockAbove != Blocks.air){
				return false;
			}
			if (block == x){
				return true;
			}else if (block == Blocks.snow && blockBelow == x){
				return true;
			}
		}
		
		return false;
	}

	public void setBlock(World world, int x, int y, int z, Block block, int metadata)
	{
		Block b1 = world.getBlock(x, y, z);

		if(b1.isAir(world, x, y, z) || b1.isLeaves(world, x, y, z))
		{
			world.setBlock(x, y, z, block, metadata, 2);
		}
	}

	public boolean generate(World world, Random rand, int i, int j, int k) {
		//check that each corner is one of the valid spawn blocks
		if(!locationIsValidSpawn(world, i, j, k) || !locationIsValidSpawn(world, i + 19, j, k) || !locationIsValidSpawn(world, i + 19, j, k + 16) || !locationIsValidSpawn(world, i, j, k + 16))
		{
			return false;
		}

		k = k - 10;
		i = i - 10;

		this.setBlock(world, i + 0, j + 0, k + 0, Blocks.planks, 0);
		this.setBlock(world, i + 0, j + 0, k + 1, Blocks.planks, 0);
		this.setBlock(world, i + 0, j + 0, k + 2, Blocks.planks, 0);
		this.setBlock(world, i + 0, j + 0, k + 3, Blocks.planks, 0);
		this.setBlock(world, i + 0, j + 0, k + 4, Blocks.planks, 0);
		this.setBlock(world, i + 0, j + 0, k + 5, Blocks.planks, 0);
		this.setBlock(world, i + 0, j + 0, k + 6, Blocks.planks, 0);
		this.setBlock(world, i + 0, j + 0, k + 7, Blocks.planks, 0);
		this.setBlock(world, i + 0, j + 0, k + 8, Blocks.planks, 0);
		this.setBlock(world, i + 0, j + 0, k + 9, Blocks.planks, 0);
		this.setBlock(world, i + 0, j + 0, k + 10, Blocks.planks, 0);
		this.setBlock(world, i + 0, j + 0, k + 11, Blocks.planks, 0);
		this.setBlock(world, i + 0, j + 0, k + 12, Blocks.planks, 0);
		this.setBlock(world, i + 0, j + 0, k + 13, Blocks.planks, 0);
		this.setBlock(world, i + 0, j + 0, k + 14, Blocks.planks, 0);
		this.setBlock(world, i + 0, j + 0, k + 15, Blocks.planks, 0);
		this.setBlock(world, i + 0, j + 0, k + 16, Blocks.planks, 0);
		this.setBlock(world, i + 0, j + 1, k + 1, Blocks.log, 0);
		this.setBlock(world, i + 0, j + 1, k + 15, Blocks.log, 0);
		this.setBlock(world, i + 0, j + 2, k + 1, Blocks.log, 0);
		this.setBlock(world, i + 0, j + 2, k + 15, Blocks.log, 0);
		this.setBlock(world, i + 0, j + 3, k + 1, Blocks.log, 0);
		this.setBlock(world, i + 0, j + 3, k + 15, Blocks.log, 0);
		this.setBlock(world, i + 0, j + 4, k + 0, Blocks.log, 0);
		this.setBlock(world, i + 0, j + 4, k + 1, Blocks.log, 0);
		this.setBlock(world, i + 0, j + 4, k + 2, Blocks.log, 0);
		this.setBlock(world, i + 0, j + 4, k + 14, Blocks.log, 0);
		this.setBlock(world, i + 0, j + 4, k + 15, Blocks.log, 0);
		this.setBlock(world, i + 0, j + 4, k + 16, Blocks.log, 0);
		this.setBlock(world, i + 1, j + 0, k + 0, Blocks.planks, 0);
		this.setBlock(world, i + 1, j + 0, k + 1, Blocks.planks, 0);
		this.setBlock(world, i + 1, j + 0, k + 2, Blocks.planks, 0);
		this.setBlock(world, i + 1, j + 0, k + 3, Blocks.planks, 0);
		this.setBlock(world, i + 1, j + 0, k + 4, Blocks.planks, 0);
		this.setBlock(world, i + 1, j + 0, k + 5, Blocks.planks, 0);
		this.setBlock(world, i + 1, j + 0, k + 6, Blocks.planks, 0);
		this.setBlock(world, i + 1, j + 0, k + 7, Blocks.planks, 0);
		this.setBlock(world, i + 1, j + 0, k + 8, Blocks.planks, 0);
		this.setBlock(world, i + 1, j + 0, k + 9, Blocks.planks, 0);
		this.setBlock(world, i + 1, j + 0, k + 10, Blocks.planks, 0);
		this.setBlock(world, i + 1, j + 0, k + 11, Blocks.planks, 0);
		this.setBlock(world, i + 1, j + 0, k + 12, Blocks.planks, 0);
		this.setBlock(world, i + 1, j + 0, k + 13, Blocks.planks, 0);
		this.setBlock(world, i + 1, j + 0, k + 14, Blocks.planks, 0);
		this.setBlock(world, i + 1, j + 0, k + 15, Blocks.planks, 0);
		this.setBlock(world, i + 1, j + 0, k + 16, Blocks.planks, 0);
		this.setBlock(world, i + 1, j + 1, k + 0, Blocks.log, 0);
		this.setBlock(world, i + 1, j + 1, k + 1, Blocks.log, 0);
		this.setBlock(world, i + 1, j + 1, k + 2, Blocks.log, 0);
		this.setBlock(world, i + 1, j + 1, k + 3, Blocks.log, 0);
		this.setBlock(world, i + 1, j + 1, k + 4, Blocks.log, 0);
		this.setBlock(world, i + 1, j + 1, k + 5, Blocks.log, 0);
		this.setBlock(world, i + 1, j + 1, k + 6, Blocks.log, 0);
		this.setBlock(world, i + 1, j + 1, k + 11, Blocks.log, 0);
		this.setBlock(world, i + 1, j + 1, k + 12, Blocks.log, 0);
		this.setBlock(world, i + 1, j + 1, k + 13, Blocks.log, 0);
		this.setBlock(world, i + 1, j + 1, k + 14, Blocks.log, 0);
		this.setBlock(world, i + 1, j + 1, k + 15, Blocks.log, 0);
		this.setBlock(world, i + 1, j + 1, k + 16, Blocks.log, 0);
		this.setBlock(world, i + 1, j + 2, k + 0, Blocks.log, 0);
		this.setBlock(world, i + 1, j + 2, k + 1, Blocks.log, 0);
		this.setBlock(world, i + 1, j + 2, k + 2, Blocks.log, 0);
		this.setBlock(world, i + 1, j + 2, k + 3, Blocks.log, 0);
		this.setBlock(world, i + 1, j + 2, k + 4, Blocks.log, 0);
		this.setBlock(world, i + 1, j + 2, k + 5, Blocks.log, 0);
		this.setBlock(world, i + 1, j + 2, k + 6, Blocks.log, 0);
		this.setBlock(world, i + 1, j + 2, k + 11, Blocks.log, 0);
		this.setBlock(world, i + 1, j + 2, k + 12, Blocks.log, 0);
		this.setBlock(world, i + 1, j + 2, k + 13, Blocks.log, 0);
		this.setBlock(world, i + 1, j + 2, k + 14, Blocks.log, 0);
		this.setBlock(world, i + 1, j + 2, k + 15, Blocks.log, 0);
		this.setBlock(world, i + 1, j + 2, k + 16, Blocks.log, 0);
		this.setBlock(world, i + 1, j + 3, k + 0, Blocks.log, 0);
		this.setBlock(world, i + 1, j + 3, k + 1, Blocks.log, 0);
		this.setBlock(world, i + 1, j + 3, k + 2, Blocks.log, 0);
		this.setBlock(world, i + 1, j + 3, k + 3, Blocks.log, 0);
		this.setBlock(world, i + 1, j + 3, k + 4, Blocks.log, 0);
		this.setBlock(world, i + 1, j + 3, k + 5, Blocks.log, 0);
		this.setBlock(world, i + 1, j + 3, k + 6, Blocks.log, 0);
		this.setBlock(world, i + 1, j + 3, k + 7, Blocks.log, 0);
		this.setBlock(world, i + 1, j + 3, k + 8, Blocks.log, 0);
		this.setBlock(world, i + 1, j + 3, k + 9, Blocks.log, 0);
		this.setBlock(world, i + 1, j + 3, k + 10, Blocks.log, 0);
		this.setBlock(world, i + 1, j + 3, k + 11, Blocks.log, 0);
		this.setBlock(world, i + 1, j + 3, k + 12, Blocks.log, 0);
		this.setBlock(world, i + 1, j + 3, k + 13, Blocks.log, 0);
		this.setBlock(world, i + 1, j + 3, k + 14, Blocks.log, 0);
		this.setBlock(world, i + 1, j + 3, k + 15, Blocks.log, 0);
		this.setBlock(world, i + 1, j + 3, k + 16, Blocks.log, 0);
		this.setBlock(world, i + 1, j + 4, k + 0, Blocks.log, 0);
		this.setBlock(world, i + 1, j + 4, k + 1, Blocks.log, 0);
		this.setBlock(world, i + 1, j + 4, k + 2, Blocks.log, 0);
		this.setBlock(world, i + 1, j + 4, k + 3, Blocks.log, 0);
		this.setBlock(world, i + 1, j + 4, k + 4, Blocks.log, 0);
		this.setBlock(world, i + 1, j + 4, k + 5, Blocks.log, 0);
		this.setBlock(world, i + 1, j + 4, k + 6, Blocks.log, 0);
		this.setBlock(world, i + 1, j + 4, k + 7, Blocks.log, 8);
		this.setBlock(world, i + 1, j + 4, k + 8, Blocks.log, 0);
		this.setBlock(world, i + 1, j + 4, k + 9, Blocks.log, 0);
		this.setBlock(world, i + 1, j + 4, k + 10, Blocks.log, 0);
		this.setBlock(world, i + 1, j + 4, k + 11, Blocks.log, 0);
		this.setBlock(world, i + 1, j + 4, k + 12, Blocks.log, 0);
		this.setBlock(world, i + 1, j + 4, k + 13, Blocks.log, 0);
		this.setBlock(world, i + 1, j + 4, k + 14, Blocks.log, 0);
		this.setBlock(world, i + 1, j + 4, k + 15, Blocks.log, 0);
		this.setBlock(world, i + 1, j + 4, k + 16, Blocks.log, 0);
		this.setBlock(world, i + 2, j + 0, k + 0, Blocks.planks, 0);
		this.setBlock(world, i + 2, j + 0, k + 1, Blocks.planks, 0);
		this.setBlock(world, i + 2, j + 0, k + 2, Blocks.planks, 0);
		this.setBlock(world, i + 2, j + 0, k + 3, Blocks.planks, 0);
		this.setBlock(world, i + 2, j + 0, k + 4, Blocks.planks, 0);
		this.setBlock(world, i + 2, j + 0, k + 5, Blocks.planks, 0);
		this.setBlock(world, i + 2, j + 0, k + 6, Blocks.planks, 0);
		this.setBlock(world, i + 2, j + 0, k + 7, Blocks.planks, 0);
		this.setBlock(world, i + 2, j + 0, k + 8, Blocks.planks, 0);
		this.setBlock(world, i + 2, j + 0, k + 9, Blocks.planks, 0);
		this.setBlock(world, i + 2, j + 0, k + 10, Blocks.planks, 0);
		this.setBlock(world, i + 2, j + 0, k + 11, Blocks.planks, 0);
		this.setBlock(world, i + 2, j + 0, k + 12, Blocks.planks, 0);
		this.setBlock(world, i + 2, j + 0, k + 13, Blocks.planks, 0);
		this.setBlock(world, i + 2, j + 0, k + 14, Blocks.planks, 0);
		this.setBlock(world, i + 2, j + 0, k + 15, Blocks.planks, 0);
		this.setBlock(world, i + 2, j + 0, k + 16, Blocks.planks, 0);
		this.setBlock(world, i + 2, j + 1, k + 1, Blocks.log, 0);
		this.setBlock(world, i + 2, j + 1, k + 15, Blocks.log, 0);
		this.setBlock(world, i + 2, j + 2, k + 1, Blocks.log, 0);
		this.setBlock(world, i + 2, j + 2, k + 15, Blocks.log, 0);
		this.setBlock(world, i + 2, j + 3, k + 1, Blocks.log, 0);
		this.setBlock(world, i + 2, j + 3, k + 15, Blocks.log, 0);
		this.setBlock(world, i + 2, j + 4, k + 0, Blocks.log, 0);
		this.setBlock(world, i + 2, j + 4, k + 1, Blocks.log, 0);
		this.setBlock(world, i + 2, j + 4, k + 2, Blocks.log, 0);
		this.setBlock(world, i + 2, j + 4, k + 14, Blocks.log, 0);
		this.setBlock(world, i + 2, j + 4, k + 15, Blocks.log, 0);
		this.setBlock(world, i + 2, j + 4, k + 16, Blocks.log, 0);
		this.setBlock(world, i + 3, j + 0, k + 0, Blocks.planks, 0);
		this.setBlock(world, i + 3, j + 0, k + 1, Blocks.planks, 0);
		this.setBlock(world, i + 3, j + 0, k + 2, Blocks.planks, 0);
		this.setBlock(world, i + 3, j + 0, k + 3, Blocks.planks, 0);
		this.setBlock(world, i + 3, j + 0, k + 4, Blocks.planks, 0);
		this.setBlock(world, i + 3, j + 0, k + 5, Blocks.planks, 0);
		this.setBlock(world, i + 3, j + 0, k + 6, Blocks.planks, 0);
		this.setBlock(world, i + 3, j + 0, k + 7, Blocks.planks, 0);
		this.setBlock(world, i + 3, j + 0, k + 8, Blocks.planks, 0);
		this.setBlock(world, i + 3, j + 0, k + 9, Blocks.planks, 0);
		this.setBlock(world, i + 3, j + 0, k + 10, Blocks.planks, 0);
		this.setBlock(world, i + 3, j + 0, k + 11, Blocks.planks, 0);
		this.setBlock(world, i + 3, j + 0, k + 12, Blocks.planks, 0);
		this.setBlock(world, i + 3, j + 0, k + 13, Blocks.planks, 0);
		this.setBlock(world, i + 3, j + 0, k + 14, Blocks.planks, 0);
		this.setBlock(world, i + 3, j + 0, k + 15, Blocks.planks, 0);
		this.setBlock(world, i + 3, j + 0, k + 16, Blocks.planks, 0);
		this.setBlock(world, i + 3, j + 1, k + 1, Blocks.log, 0);
		this.setBlock(world, i + 3, j + 1, k + 2, Blocks.wool, 11);
		this.setBlock(world, i + 3, j + 1, k + 15, Blocks.log, 0);
		this.setBlock(world, i + 3, j + 2, k + 1, Blocks.log, 0);
		this.setBlock(world, i + 3, j + 2, k + 2, Blocks.stone, 3);
		this.setBlock(world, i + 3, j + 2, k + 15, Blocks.log, 0);
		this.setBlock(world, i + 3, j + 3, k + 1, Blocks.log, 0);
		this.setBlock(world, i + 3, j + 3, k + 2, Blocks.air, 1);
		this.setBlock(world, i + 3, j + 3, k + 15, Blocks.log, 0);
		this.setBlock(world, i + 3, j + 4, k + 1, Blocks.log, 0);
		this.setBlock(world, i + 3, j + 4, k + 15, Blocks.log, 4);
		this.setBlock(world, i + 4, j + 0, k + 0, Blocks.planks, 0);
		this.setBlock(world, i + 4, j + 0, k + 1, Blocks.planks, 0);
		this.setBlock(world, i + 4, j + 0, k + 2, Blocks.planks, 0);
		this.setBlock(world, i + 4, j + 0, k + 3, Blocks.planks, 0);
		this.setBlock(world, i + 4, j + 0, k + 4, Blocks.planks, 0);
		this.setBlock(world, i + 4, j + 0, k + 5, Blocks.planks, 0);
		this.setBlock(world, i + 4, j + 0, k + 6, Blocks.planks, 0);
		this.setBlock(world, i + 4, j + 0, k + 7, Blocks.planks, 0);
		this.setBlock(world, i + 4, j + 0, k + 8, Blocks.planks, 0);
		this.setBlock(world, i + 4, j + 0, k + 9, Blocks.planks, 0);
		this.setBlock(world, i + 4, j + 0, k + 10, Blocks.planks, 0);
		this.setBlock(world, i + 4, j + 0, k + 11, Blocks.planks, 0);
		this.setBlock(world, i + 4, j + 0, k + 12, Blocks.planks, 0);
		this.setBlock(world, i + 4, j + 0, k + 13, Blocks.planks, 0);
		this.setBlock(world, i + 4, j + 0, k + 14, Blocks.planks, 0);
		this.setBlock(world, i + 4, j + 0, k + 15, Blocks.planks, 0);
		this.setBlock(world, i + 4, j + 0, k + 16, Blocks.planks, 0);
		this.setBlock(world, i + 4, j + 1, k + 1, Blocks.log, 0);
		this.setBlock(world, i + 4, j + 1, k + 15, Blocks.log, 0);
		this.setBlock(world, i + 4, j + 2, k + 1, Blocks.log, 0);
		this.setBlock(world, i + 4, j + 2, k + 15, Blocks.log, 0);
		this.setBlock(world, i + 4, j + 3, k + 1, Blocks.log, 0);
		this.setBlock(world, i + 4, j + 3, k + 15, Blocks.log, 0);
		this.setBlock(world, i + 4, j + 4, k + 1, Blocks.log, 0);
		this.setBlock(world, i + 4, j + 4, k + 15, Blocks.log, 4);
		this.setBlock(world, i + 5, j + 0, k + 0, Blocks.planks, 0);
		this.setBlock(world, i + 5, j + 0, k + 1, Blocks.planks, 0);
		this.setBlock(world, i + 5, j + 0, k + 2, Blocks.planks, 0);
		this.setBlock(world, i + 5, j + 0, k + 3, Blocks.planks, 0);
		this.setBlock(world, i + 5, j + 0, k + 4, Blocks.planks, 0);
		this.setBlock(world, i + 5, j + 0, k + 5, Blocks.planks, 0);
		this.setBlock(world, i + 5, j + 0, k + 6, Blocks.planks, 0);
		this.setBlock(world, i + 5, j + 0, k + 7, Blocks.planks, 0);
		this.setBlock(world, i + 5, j + 0, k + 8, Blocks.planks, 0);
		this.setBlock(world, i + 5, j + 0, k + 9, Blocks.planks, 0);
		this.setBlock(world, i + 5, j + 0, k + 10, Blocks.planks, 0);
		this.setBlock(world, i + 5, j + 0, k + 11, Blocks.planks, 0);
		this.setBlock(world, i + 5, j + 0, k + 12, Blocks.planks, 0);
		this.setBlock(world, i + 5, j + 0, k + 13, Blocks.planks, 0);
		this.setBlock(world, i + 5, j + 0, k + 14, Blocks.planks, 0);
		this.setBlock(world, i + 5, j + 0, k + 15, Blocks.planks, 0);
		this.setBlock(world, i + 5, j + 0, k + 16, Blocks.planks, 0);
		this.setBlock(world, i + 5, j + 1, k + 1, Blocks.log, 0);
		this.setBlock(world, i + 5, j + 1, k + 15, Blocks.log, 0);
		this.setBlock(world, i + 5, j + 2, k + 1, Blocks.log, 0);
		this.setBlock(world, i + 5, j + 2, k + 15, Blocks.log, 0);
		this.setBlock(world, i + 5, j + 3, k + 1, Blocks.log, 0);
		this.setBlock(world, i + 5, j + 3, k + 3, Blocks.wool, 4);
		this.setBlock(world, i + 5, j + 3, k + 4, Blocks.wool, 4);
		this.setBlock(world, i + 5, j + 3, k + 5, Blocks.wool, 4);
		this.setBlock(world, i + 5, j + 3, k + 6, Blocks.wool, 4);
		this.setBlock(world, i + 5, j + 3, k + 7, Blocks.wool, 4);
		this.setBlock(world, i + 5, j + 3, k + 8, Blocks.wool, 4);
		this.setBlock(world, i + 5, j + 3, k + 9, Blocks.wool, 4);
		this.setBlock(world, i + 5, j + 3, k + 10, Blocks.wool, 4);
		this.setBlock(world, i + 5, j + 3, k + 15, Blocks.log, 0);
		this.setBlock(world, i + 5, j + 4, k + 1, Blocks.log, 0);
		this.setBlock(world, i + 5, j + 4, k + 15, Blocks.log, 4);
		this.setBlock(world, i + 6, j + 0, k + 0, Blocks.planks, 0);
		this.setBlock(world, i + 6, j + 0, k + 1, Blocks.planks, 0);
		this.setBlock(world, i + 6, j + 0, k + 2, Blocks.planks, 0);
		this.setBlock(world, i + 6, j + 0, k + 3, Blocks.planks, 0);
		this.setBlock(world, i + 6, j + 0, k + 4, Blocks.planks, 0);
		this.setBlock(world, i + 6, j + 0, k + 5, Blocks.planks, 0);
		this.setBlock(world, i + 6, j + 0, k + 6, Blocks.planks, 0);
		this.setBlock(world, i + 6, j + 0, k + 7, Blocks.planks, 0);
		this.setBlock(world, i + 6, j + 0, k + 8, Blocks.planks, 0);
		this.setBlock(world, i + 6, j + 0, k + 9, Blocks.planks, 0);
		this.setBlock(world, i + 6, j + 0, k + 10, Blocks.planks, 0);
		this.setBlock(world, i + 6, j + 0, k + 11, Blocks.planks, 0);
		this.setBlock(world, i + 6, j + 0, k + 12, Blocks.planks, 0);
		this.setBlock(world, i + 6, j + 0, k + 13, Blocks.planks, 0);
		this.setBlock(world, i + 6, j + 0, k + 14, Blocks.planks, 0);
		this.setBlock(world, i + 6, j + 0, k + 15, Blocks.planks, 0);
		this.setBlock(world, i + 6, j + 0, k + 16, Blocks.planks, 0);
		this.setBlock(world, i + 6, j + 1, k + 1, Blocks.log, 0);
		this.setBlock(world, i + 6, j + 1, k + 3, Blocks.fence, 0);
		this.setBlock(world, i + 6, j + 1, k + 4, Blocks.log, 0);
		this.setBlock(world, i + 6, j + 1, k + 5, Blocks.fence, 0);
		this.setBlock(world, i + 6, j + 1, k + 6, Blocks.fence_gate, 3);
		this.setBlock(world, i + 6, j + 1, k + 7, Blocks.fence_gate, 1);
		this.setBlock(world, i + 6, j + 1, k + 8, Blocks.fence, 0);
		this.setBlock(world, i + 6, j + 1, k + 9, Blocks.log, 0);
		this.setBlock(world, i + 6, j + 1, k + 15, Blocks.log, 0);
		this.setBlock(world, i + 6, j + 2, k + 1, Blocks.log, 0);
		this.setBlock(world, i + 6, j + 2, k + 4, Blocks.log, 0);
		this.setBlock(world, i + 6, j + 2, k + 9, Blocks.log, 0);
		this.setBlock(world, i + 6, j + 2, k + 15, Blocks.log, 0);
		this.setBlock(world, i + 6, j + 3, k + 1, Blocks.log, 0);
		this.setBlock(world, i + 6, j + 3, k + 3, Blocks.wool, 4);
		this.setBlock(world, i + 6, j + 3, k + 4, Blocks.log, 0);
		this.setBlock(world, i + 6, j + 3, k + 9, Blocks.log, 0);
		this.setBlock(world, i + 6, j + 3, k + 10, Blocks.wool, 4);
		this.setBlock(world, i + 6, j + 3, k + 15, Blocks.log, 0);
		this.setBlock(world, i + 6, j + 4, k + 1, Blocks.log, 4);
		this.setBlock(world, i + 6, j + 4, k + 4, Blocks.wool, 4);
		this.setBlock(world, i + 6, j + 4, k + 5, Blocks.wool, 4);
		this.setBlock(world, i + 6, j + 4, k + 6, Blocks.wool, 4);
		this.setBlock(world, i + 6, j + 4, k + 7, Blocks.wool, 4);
		this.setBlock(world, i + 6, j + 4, k + 8, Blocks.wool, 4);
		this.setBlock(world, i + 6, j + 4, k + 9, Blocks.wool, 4);
		this.setBlock(world, i + 6, j + 4, k + 15, Blocks.log, 4);
		this.setBlock(world, i + 7, j + 0, k + 0, Blocks.planks, 0);
		this.setBlock(world, i + 7, j + 0, k + 1, Blocks.planks, 0);
		this.setBlock(world, i + 7, j + 0, k + 2, Blocks.planks, 0);
		this.setBlock(world, i + 7, j + 0, k + 3, Blocks.planks, 0);
		this.setBlock(world, i + 7, j + 0, k + 4, Blocks.planks, 0);
		this.setBlock(world, i + 7, j + 0, k + 5, Blocks.planks, 0);
		this.setBlock(world, i + 7, j + 0, k + 6, Blocks.planks, 0);
		this.setBlock(world, i + 7, j + 0, k + 7, Blocks.planks, 0);
		this.setBlock(world, i + 7, j + 0, k + 8, Blocks.planks, 0);
		this.setBlock(world, i + 7, j + 0, k + 9, Blocks.planks, 0);
		this.setBlock(world, i + 7, j + 0, k + 10, Blocks.planks, 0);
		this.setBlock(world, i + 7, j + 0, k + 11, Blocks.planks, 0);
		this.setBlock(world, i + 7, j + 0, k + 12, Blocks.planks, 0);
		this.setBlock(world, i + 7, j + 0, k + 13, Blocks.planks, 0);
		this.setBlock(world, i + 7, j + 0, k + 14, Blocks.planks, 0);
		this.setBlock(world, i + 7, j + 0, k + 15, Blocks.planks, 0);
		this.setBlock(world, i + 7, j + 0, k + 16, Blocks.planks, 0);
		this.setBlock(world, i + 7, j + 1, k + 1, Blocks.log, 0);
		this.setBlock(world, i + 7, j + 1, k + 3, Blocks.fence, 0);
		this.setBlock(world, i + 7, j + 1, k + 9, Blocks.fence, 0);
		this.setBlock(world, i + 7, j + 1, k + 15, Blocks.log, 0);
		this.setBlock(world, i + 7, j + 2, k + 1, Blocks.log, 0);
		this.setBlock(world, i + 7, j + 2, k + 15, Blocks.log, 0);
		this.setBlock(world, i + 7, j + 3, k + 1, Blocks.log, 0);
		this.setBlock(world, i + 7, j + 3, k + 3, Blocks.wool, 4);
		this.setBlock(world, i + 7, j + 3, k + 10, Blocks.wool, 4);
		this.setBlock(world, i + 7, j + 3, k + 15, Blocks.log, 0);
		this.setBlock(world, i + 7, j + 4, k + 1, Blocks.log, 4);
		this.setBlock(world, i + 7, j + 4, k + 4, Blocks.wool, 4);
		this.setBlock(world, i + 7, j + 4, k + 9, Blocks.wool, 4);
		this.setBlock(world, i + 7, j + 4, k + 15, Blocks.log, 0);
		this.setBlock(world, i + 7, j + 5, k + 5, Blocks.wool, 4);
		this.setBlock(world, i + 7, j + 5, k + 6, Blocks.wool, 4);
		this.setBlock(world, i + 7, j + 5, k + 7, Blocks.wool, 4);
		this.setBlock(world, i + 7, j + 5, k + 8, Blocks.wool, 4);
		this.setBlock(world, i + 8, j + 0, k + 0, Blocks.planks, 0);
		this.setBlock(world, i + 8, j + 0, k + 1, Blocks.planks, 0);
		this.setBlock(world, i + 8, j + 0, k + 2, Blocks.planks, 0);
		this.setBlock(world, i + 8, j + 0, k + 3, Blocks.planks, 0);
		this.setBlock(world, i + 8, j + 0, k + 4, Blocks.planks, 0);
		this.setBlock(world, i + 8, j + 0, k + 5, Blocks.planks, 0);
		this.setBlock(world, i + 8, j + 0, k + 6, Blocks.planks, 0);
		this.setBlock(world, i + 8, j + 0, k + 7, Blocks.planks, 0);
		this.setBlock(world, i + 8, j + 0, k + 8, Blocks.planks, 0);
		this.setBlock(world, i + 8, j + 0, k + 9, Blocks.planks, 0);
		this.setBlock(world, i + 8, j + 0, k + 10, Blocks.planks, 0);
		this.setBlock(world, i + 8, j + 0, k + 11, Blocks.planks, 0);
		this.setBlock(world, i + 8, j + 0, k + 12, Blocks.planks, 0);
		this.setBlock(world, i + 8, j + 0, k + 13, Blocks.planks, 0);
		this.setBlock(world, i + 8, j + 0, k + 14, Blocks.planks, 0);
		this.setBlock(world, i + 8, j + 0, k + 15, Blocks.planks, 0);
		this.setBlock(world, i + 8, j + 0, k + 16, Blocks.planks, 0);
		this.setBlock(world, i + 8, j + 1, k + 1, Blocks.log, 0);
		this.setBlock(world, i + 8, j + 1, k + 3, Blocks.fence, 0);
		this.setBlock(world, i + 8, j + 1, k + 9, Blocks.fence, 0);
		this.setBlock(world, i + 8, j + 1, k + 15, Blocks.log, 0);
		this.setBlock(world, i + 8, j + 2, k + 1, Blocks.log, 0);
		this.setBlock(world, i + 8, j + 2, k + 15, Blocks.log, 0);
		this.setBlock(world, i + 8, j + 3, k + 1, Blocks.log, 0);
		this.setBlock(world, i + 8, j + 3, k + 3, Blocks.wool, 4);
		this.setBlock(world, i + 8, j + 3, k + 10, Blocks.wool, 4);
		this.setBlock(world, i + 8, j + 3, k + 15, Blocks.log, 0);
		this.setBlock(world, i + 8, j + 4, k + 1, Blocks.log, 4);
		this.setBlock(world, i + 8, j + 4, k + 4, Blocks.wool, 4);
		this.setBlock(world, i + 8, j + 4, k + 9, Blocks.wool, 4);
		this.setBlock(world, i + 8, j + 4, k + 15, Blocks.log, 0);
		this.setBlock(world, i + 8, j + 5, k + 5, Blocks.wool, 4);
		this.setBlock(world, i + 8, j + 5, k + 6, Blocks.wool, 4);
		this.setBlock(world, i + 8, j + 5, k + 7, Blocks.wool, 4);
		this.setBlock(world, i + 8, j + 5, k + 8, Blocks.wool, 4);
		this.setBlock(world, i + 9, j + 0, k + 0, Blocks.planks, 0);
		this.setBlock(world, i + 9, j + 0, k + 1, Blocks.planks, 0);
		this.setBlock(world, i + 9, j + 0, k + 2, Blocks.planks, 0);
		this.setBlock(world, i + 9, j + 0, k + 3, Blocks.planks, 0);
		this.setBlock(world, i + 9, j + 0, k + 4, Blocks.planks, 0);
		this.setBlock(world, i + 9, j + 0, k + 5, Blocks.planks, 0);
		this.setBlock(world, i + 9, j + 0, k + 6, Blocks.planks, 0);
		this.setBlock(world, i + 9, j + 0, k + 7, Blocks.planks, 0);
		this.setBlock(world, i + 9, j + 0, k + 8, Blocks.planks, 0);
		this.setBlock(world, i + 9, j + 0, k + 9, Blocks.planks, 0);
		this.setBlock(world, i + 9, j + 0, k + 10, Blocks.planks, 0);
		this.setBlock(world, i + 9, j + 0, k + 11, Blocks.planks, 0);
		this.setBlock(world, i + 9, j + 0, k + 12, Blocks.planks, 0);
		this.setBlock(world, i + 9, j + 0, k + 13, Blocks.planks, 0);
		this.setBlock(world, i + 9, j + 0, k + 14, Blocks.planks, 0);
		this.setBlock(world, i + 9, j + 0, k + 15, Blocks.planks, 0);
		this.setBlock(world, i + 9, j + 0, k + 16, Blocks.planks, 0);
		this.setBlock(world, i + 9, j + 1, k + 1, Blocks.log, 0);
		this.setBlock(world, i + 9, j + 1, k + 3, Blocks.fence, 0);
		this.setBlock(world, i + 9, j + 1, k + 9, Blocks.fence, 0);
		this.setBlock(world, i + 9, j + 1, k + 15, Blocks.log, 0);
		this.setBlock(world, i + 9, j + 2, k + 1, Blocks.log, 0);
		this.setBlock(world, i + 9, j + 2, k + 15, Blocks.log, 0);
		this.setBlock(world, i + 9, j + 3, k + 1, Blocks.log, 0);
		this.setBlock(world, i + 9, j + 3, k + 3, Blocks.wool, 4);
		this.setBlock(world, i + 9, j + 3, k + 10, Blocks.wool, 4);
		this.setBlock(world, i + 9, j + 3, k + 15, Blocks.log, 0);
		this.setBlock(world, i + 9, j + 4, k + 1, Blocks.log, 4);
		this.setBlock(world, i + 9, j + 4, k + 4, Blocks.wool, 4);
		this.setBlock(world, i + 9, j + 4, k + 9, Blocks.wool, 4);
		this.setBlock(world, i + 9, j + 4, k + 15, Blocks.log, 0);
		this.setBlock(world, i + 9, j + 5, k + 5, Blocks.wool, 4);
		this.setBlock(world, i + 9, j + 5, k + 6, Blocks.wool, 4);
		this.setBlock(world, i + 9, j + 5, k + 7, Blocks.wool, 4);
		this.setBlock(world, i + 9, j + 5, k + 8, Blocks.wool, 4);
		this.setBlock(world, i + 10, j + 0, k + 0, Blocks.planks, 0);
		this.setBlock(world, i + 10, j + 0, k + 1, Blocks.planks, 0);
		this.setBlock(world, i + 10, j + 0, k + 2, Blocks.planks, 0);
		this.setBlock(world, i + 10, j + 0, k + 3, Blocks.planks, 0);
		this.setBlock(world, i + 10, j + 0, k + 4, Blocks.planks, 0);
		this.setBlock(world, i + 10, j + 0, k + 5, Blocks.planks, 0);
		this.setBlock(world, i + 10, j + 0, k + 6, Blocks.planks, 0);
		this.setBlock(world, i + 10, j + 0, k + 7, Blocks.planks, 0);
		this.setBlock(world, i + 10, j + 0, k + 8, Blocks.planks, 0);
		this.setBlock(world, i + 10, j + 0, k + 9, Blocks.planks, 0);
		this.setBlock(world, i + 10, j + 0, k + 10, Blocks.planks, 0);
		this.setBlock(world, i + 10, j + 0, k + 11, Blocks.planks, 0);
		this.setBlock(world, i + 10, j + 0, k + 12, Blocks.planks, 0);
		this.setBlock(world, i + 10, j + 0, k + 13, Blocks.planks, 0);
		this.setBlock(world, i + 10, j + 0, k + 14, Blocks.planks, 0);
		this.setBlock(world, i + 10, j + 0, k + 15, Blocks.planks, 0);
		this.setBlock(world, i + 10, j + 0, k + 16, Blocks.planks, 0);
		this.setBlock(world, i + 10, j + 1, k + 1, Blocks.log, 0);
		this.setBlock(world, i + 10, j + 1, k + 3, Blocks.fence, 0);
		this.setBlock(world, i + 10, j + 1, k + 5, Blocks.furnace, 3);
		this.setBlock(world, i + 10, j + 1, k + 9, Blocks.fence, 0);
		this.setBlock(world, i + 10, j + 1, k + 15, Blocks.log, 0);
		this.setBlock(world, i + 10, j + 2, k + 1, Blocks.log, 0);
		this.setBlock(world, i + 10, j + 2, k + 15, Blocks.log, 0);
		this.setBlock(world, i + 10, j + 3, k + 1, Blocks.log, 0);
		this.setBlock(world, i + 10, j + 3, k + 3, Blocks.wool, 4);
		this.setBlock(world, i + 10, j + 3, k + 10, Blocks.wool, 4);
		this.setBlock(world, i + 10, j + 3, k + 15, Blocks.log, 0);
		this.setBlock(world, i + 10, j + 4, k + 1, Blocks.log, 4);
		this.setBlock(world, i + 10, j + 4, k + 4, Blocks.wool, 4);
		this.setBlock(world, i + 10, j + 4, k + 9, Blocks.wool, 4);
		this.setBlock(world, i + 10, j + 4, k + 15, Blocks.log, 4);
		this.setBlock(world, i + 10, j + 5, k + 5, Blocks.wool, 4);
		this.setBlock(world, i + 10, j + 5, k + 6, Blocks.wool, 4);
		this.setBlock(world, i + 10, j + 5, k + 7, Blocks.wool, 4);
		this.setBlock(world, i + 10, j + 5, k + 8, Blocks.wool, 4);
		this.setBlock(world, i + 11, j + 0, k + 0, Blocks.planks, 0);
		this.setBlock(world, i + 11, j + 0, k + 1, Blocks.planks, 0);
		this.setBlock(world, i + 11, j + 0, k + 2, Blocks.planks, 0);
		this.setBlock(world, i + 11, j + 0, k + 3, Blocks.planks, 0);
		this.setBlock(world, i + 11, j + 0, k + 4, Blocks.planks, 0);
		this.setBlock(world, i + 11, j + 0, k + 5, Blocks.planks, 0);
		this.setBlock(world, i + 11, j + 0, k + 6, Blocks.planks, 0);
		this.setBlock(world, i + 11, j + 0, k + 7, Blocks.planks, 0);
		this.setBlock(world, i + 11, j + 0, k + 8, Blocks.planks, 0);
		this.setBlock(world, i + 11, j + 0, k + 9, Blocks.planks, 0);
		this.setBlock(world, i + 11, j + 0, k + 10, Blocks.planks, 0);
		this.setBlock(world, i + 11, j + 0, k + 11, Blocks.planks, 0);
		this.setBlock(world, i + 11, j + 0, k + 12, Blocks.planks, 0);
		this.setBlock(world, i + 11, j + 0, k + 13, Blocks.planks, 0);
		this.setBlock(world, i + 11, j + 0, k + 14, Blocks.planks, 0);
		this.setBlock(world, i + 11, j + 0, k + 15, Blocks.planks, 0);
		this.setBlock(world, i + 11, j + 0, k + 16, Blocks.planks, 0);
		this.setBlock(world, i + 11, j + 1, k + 1, Blocks.log, 0);
		this.setBlock(world, i + 11, j + 1, k + 3, Blocks.fence, 0);
		this.setBlock(world, i + 11, j + 1, k + 5, Blocks.furnace, 3);
		this.setBlock(world, i + 11, j + 1, k + 9, Blocks.fence, 0);
		this.setBlock(world, i + 11, j + 1, k + 15, Blocks.log, 0);
		this.setBlock(world, i + 11, j + 2, k + 1, Blocks.log, 0);
		this.setBlock(world, i + 11, j + 2, k + 15, Blocks.log, 0);
		this.setBlock(world, i + 11, j + 3, k + 1, Blocks.log, 0);
		this.setBlock(world, i + 11, j + 3, k + 3, Blocks.wool, 4);
		this.setBlock(world, i + 11, j + 3, k + 10, Blocks.wool, 4);
		this.setBlock(world, i + 11, j + 3, k + 15, Blocks.log, 0);
		this.setBlock(world, i + 11, j + 4, k + 1, Blocks.log, 4);
		this.setBlock(world, i + 11, j + 4, k + 4, Blocks.wool, 4);
		this.setBlock(world, i + 11, j + 4, k + 9, Blocks.wool, 4);
		this.setBlock(world, i + 11, j + 4, k + 15, Blocks.log, 0);
		this.setBlock(world, i + 11, j + 5, k + 5, Blocks.wool, 4);
		this.setBlock(world, i + 11, j + 5, k + 6, Blocks.wool, 4);
		this.setBlock(world, i + 11, j + 5, k + 7, Blocks.wool, 4);
		this.setBlock(world, i + 11, j + 5, k + 8, Blocks.wool, 4);
		this.setBlock(world, i + 12, j + 0, k + 0, Blocks.planks, 0);
		this.setBlock(world, i + 12, j + 0, k + 1, Blocks.planks, 0);
		this.setBlock(world, i + 12, j + 0, k + 2, Blocks.planks, 0);
		this.setBlock(world, i + 12, j + 0, k + 3, Blocks.planks, 0);
		this.setBlock(world, i + 12, j + 0, k + 4, Blocks.planks, 0);
		this.setBlock(world, i + 12, j + 0, k + 5, Blocks.planks, 0);
		this.setBlock(world, i + 12, j + 0, k + 6, Blocks.planks, 0);
		this.setBlock(world, i + 12, j + 0, k + 7, Blocks.planks, 0);
		this.setBlock(world, i + 12, j + 0, k + 8, Blocks.planks, 0);
		this.setBlock(world, i + 12, j + 0, k + 9, Blocks.planks, 0);
		this.setBlock(world, i + 12, j + 0, k + 10, Blocks.planks, 0);
		this.setBlock(world, i + 12, j + 0, k + 11, Blocks.planks, 0);
		this.setBlock(world, i + 12, j + 0, k + 12, Blocks.planks, 0);
		this.setBlock(world, i + 12, j + 0, k + 13, Blocks.planks, 0);
		this.setBlock(world, i + 12, j + 0, k + 14, Blocks.planks, 0);
		this.setBlock(world, i + 12, j + 0, k + 15, Blocks.planks, 0);
		this.setBlock(world, i + 12, j + 0, k + 16, Blocks.planks, 0);
		this.setBlock(world, i + 12, j + 1, k + 1, Blocks.log, 0);
		this.setBlock(world, i + 12, j + 1, k + 3, Blocks.fence, 0);
		this.setBlock(world, i + 12, j + 1, k + 5, Blocks.air, 1);
		this.setBlock(world, i + 12, j + 1, k + 9, Blocks.fence, 0);
		this.setBlock(world, i + 12, j + 1, k + 15, Blocks.log, 0);
		this.setBlock(world, i + 12, j + 2, k + 1, Blocks.log, 0);
		this.setBlock(world, i + 12, j + 2, k + 15, Blocks.log, 0);
		this.setBlock(world, i + 12, j + 3, k + 1, Blocks.log, 0);
		this.setBlock(world, i + 12, j + 3, k + 3, Blocks.wool, 4);
		this.setBlock(world, i + 12, j + 3, k + 10, Blocks.wool, 4);
		this.setBlock(world, i + 12, j + 3, k + 15, Blocks.log, 0);
		this.setBlock(world, i + 12, j + 4, k + 1, Blocks.log, 4);
		this.setBlock(world, i + 12, j + 4, k + 4, Blocks.wool, 4);
		this.setBlock(world, i + 12, j + 4, k + 9, Blocks.wool, 4);
		this.setBlock(world, i + 12, j + 4, k + 15, Blocks.log, 4);
		this.setBlock(world, i + 12, j + 5, k + 5, Blocks.wool, 4);
		this.setBlock(world, i + 12, j + 5, k + 6, Blocks.wool, 4);
		this.setBlock(world, i + 12, j + 5, k + 7, Blocks.wool, 4);
		this.setBlock(world, i + 12, j + 5, k + 8, Blocks.wool, 4);
		this.setBlock(world, i + 13, j + 0, k + 0, Blocks.planks, 0);
		this.setBlock(world, i + 13, j + 0, k + 1, Blocks.planks, 0);
		this.setBlock(world, i + 13, j + 0, k + 2, Blocks.planks, 0);
		this.setBlock(world, i + 13, j + 0, k + 3, Blocks.planks, 0);
		this.setBlock(world, i + 13, j + 0, k + 4, Blocks.planks, 0);
		this.setBlock(world, i + 13, j + 0, k + 5, Blocks.planks, 0);
		this.setBlock(world, i + 13, j + 0, k + 6, Blocks.planks, 0);
		this.setBlock(world, i + 13, j + 0, k + 7, Blocks.planks, 0);
		this.setBlock(world, i + 13, j + 0, k + 8, Blocks.planks, 0);
		this.setBlock(world, i + 13, j + 0, k + 9, Blocks.planks, 0);
		this.setBlock(world, i + 13, j + 0, k + 10, Blocks.planks, 0);
		this.setBlock(world, i + 13, j + 0, k + 11, Blocks.planks, 0);
		this.setBlock(world, i + 13, j + 0, k + 12, Blocks.planks, 0);
		this.setBlock(world, i + 13, j + 0, k + 13, Blocks.planks, 0);
		this.setBlock(world, i + 13, j + 0, k + 14, Blocks.planks, 0);
		this.setBlock(world, i + 13, j + 0, k + 15, Blocks.planks, 0);
		this.setBlock(world, i + 13, j + 0, k + 16, Blocks.planks, 0);
		this.setBlock(world, i + 13, j + 1, k + 1, Blocks.log, 0);
		this.setBlock(world, i + 13, j + 1, k + 3, Blocks.fence, 0);
		this.setBlock(world, i + 13, j + 1, k + 9, Blocks.fence, 0);
		this.setBlock(world, i + 13, j + 1, k + 15, Blocks.log, 0);
		this.setBlock(world, i + 13, j + 2, k + 1, Blocks.log, 0);
		this.setBlock(world, i + 13, j + 2, k + 15, Blocks.log, 0);
		this.setBlock(world, i + 13, j + 3, k + 1, Blocks.log, 0);
		this.setBlock(world, i + 13, j + 3, k + 3, Blocks.wool, 4);
		this.setBlock(world, i + 13, j + 3, k + 10, Blocks.wool, 4);
		this.setBlock(world, i + 13, j + 3, k + 15, Blocks.log, 0);
		this.setBlock(world, i + 13, j + 4, k + 1, Blocks.log, 4);
		this.setBlock(world, i + 13, j + 4, k + 4, Blocks.wool, 4);
		this.setBlock(world, i + 13, j + 4, k + 9, Blocks.wool, 4);
		this.setBlock(world, i + 13, j + 4, k + 15, Blocks.log, 0);
		this.setBlock(world, i + 13, j + 5, k + 5, Blocks.wool, 4);
		this.setBlock(world, i + 13, j + 5, k + 6, Blocks.wool, 4);
		this.setBlock(world, i + 13, j + 5, k + 7, Blocks.wool, 4);
		this.setBlock(world, i + 13, j + 5, k + 8, Blocks.wool, 4);
		this.setBlock(world, i + 14, j + 0, k + 0, Blocks.planks, 0);
		this.setBlock(world, i + 14, j + 0, k + 1, Blocks.planks, 0);
		this.setBlock(world, i + 14, j + 0, k + 2, Blocks.planks, 0);
		this.setBlock(world, i + 14, j + 0, k + 3, Blocks.planks, 0);
		this.setBlock(world, i + 14, j + 0, k + 4, Blocks.planks, 0);
		this.setBlock(world, i + 14, j + 0, k + 5, Blocks.planks, 0);
		this.setBlock(world, i + 14, j + 0, k + 6, Blocks.planks, 0);
		this.setBlock(world, i + 14, j + 0, k + 7, Blocks.planks, 0);
		this.setBlock(world, i + 14, j + 0, k + 8, Blocks.planks, 0);
		this.setBlock(world, i + 14, j + 0, k + 9, Blocks.planks, 0);
		this.setBlock(world, i + 14, j + 0, k + 10, Blocks.planks, 0);
		this.setBlock(world, i + 14, j + 0, k + 11, Blocks.planks, 0);
		this.setBlock(world, i + 14, j + 0, k + 12, Blocks.planks, 0);
		this.setBlock(world, i + 14, j + 0, k + 13, Blocks.planks, 0);
		this.setBlock(world, i + 14, j + 0, k + 14, Blocks.planks, 0);
		this.setBlock(world, i + 14, j + 0, k + 15, Blocks.planks, 0);
		this.setBlock(world, i + 14, j + 0, k + 16, Blocks.planks, 0);
		this.setBlock(world, i + 14, j + 1, k + 1, Blocks.log, 0);
		this.setBlock(world, i + 14, j + 1, k + 3, Blocks.fence, 0);
		this.setBlock(world, i + 14, j + 1, k + 7, Blocks.chest, 4);
		this.setBlock(world, i + 14, j + 1, k + 8, Blocks.chest, 4);
		this.setBlock(world, i + 14, j + 1, k + 9, Blocks.fence, 0);
		this.setBlock(world, i + 14, j + 1, k + 15, Blocks.log, 0);
		this.setBlock(world, i + 14, j + 2, k + 1, Blocks.log, 0);
		this.setBlock(world, i + 14, j + 2, k + 15, Blocks.log, 0);
		this.setBlock(world, i + 14, j + 3, k + 1, Blocks.log, 0);
		this.setBlock(world, i + 14, j + 3, k + 3, Blocks.wool, 4);
		this.setBlock(world, i + 14, j + 3, k + 10, Blocks.wool, 4);
		this.setBlock(world, i + 14, j + 3, k + 15, Blocks.log, 0);
		this.setBlock(world, i + 14, j + 4, k + 1, Blocks.log, 0);
		this.setBlock(world, i + 14, j + 4, k + 4, Blocks.wool, 4);
		this.setBlock(world, i + 14, j + 4, k + 9, Blocks.wool, 4);
		this.setBlock(world, i + 14, j + 4, k + 15, Blocks.log, 0);
		this.setBlock(world, i + 14, j + 5, k + 5, Blocks.wool, 4);
		this.setBlock(world, i + 14, j + 5, k + 6, Blocks.wool, 4);
		this.setBlock(world, i + 14, j + 5, k + 7, Blocks.wool, 4);
		this.setBlock(world, i + 14, j + 5, k + 8, Blocks.wool, 4);
		this.setBlock(world, i + 15, j + 0, k + 0, Blocks.planks, 0);
		this.setBlock(world, i + 15, j + 0, k + 1, Blocks.planks, 0);
		this.setBlock(world, i + 15, j + 0, k + 2, Blocks.planks, 0);
		this.setBlock(world, i + 15, j + 0, k + 3, Blocks.planks, 0);
		this.setBlock(world, i + 15, j + 0, k + 4, Blocks.planks, 0);
		this.setBlock(world, i + 15, j + 0, k + 5, Blocks.planks, 0);
		this.setBlock(world, i + 15, j + 0, k + 6, Blocks.planks, 0);
		this.setBlock(world, i + 15, j + 0, k + 7, Blocks.planks, 0);
		this.setBlock(world, i + 15, j + 0, k + 8, Blocks.planks, 0);
		this.setBlock(world, i + 15, j + 0, k + 9, Blocks.planks, 0);
		this.setBlock(world, i + 15, j + 0, k + 10, Blocks.planks, 0);
		this.setBlock(world, i + 15, j + 0, k + 11, Blocks.planks, 0);
		this.setBlock(world, i + 15, j + 0, k + 12, Blocks.planks, 0);
		this.setBlock(world, i + 15, j + 0, k + 13, Blocks.planks, 0);
		this.setBlock(world, i + 15, j + 0, k + 14, Blocks.planks, 0);
		this.setBlock(world, i + 15, j + 0, k + 15, Blocks.planks, 0);
		this.setBlock(world, i + 15, j + 0, k + 16, Blocks.planks, 0);
		this.setBlock(world, i + 15, j + 1, k + 1, Blocks.log, 0);
		this.setBlock(world, i + 15, j + 1, k + 3, Blocks.fence, 0);
		this.setBlock(world, i + 15, j + 1, k + 4, Blocks.log, 0);
		this.setBlock(world, i + 15, j + 1, k + 5, Blocks.fence, 0);
		this.setBlock(world, i + 15, j + 1, k + 6, Blocks.fence, 0);
		this.setBlock(world, i + 15, j + 1, k + 7, Blocks.fence, 0);
		this.setBlock(world, i + 15, j + 1, k + 8, Blocks.fence, 0);
		this.setBlock(world, i + 15, j + 1, k + 9, Blocks.log, 0);
		this.setBlock(world, i + 15, j + 1, k + 15, Blocks.log, 0);
		this.setBlock(world, i + 15, j + 2, k + 1, Blocks.log, 0);
		this.setBlock(world, i + 15, j + 2, k + 4, Blocks.log, 0);
		this.setBlock(world, i + 15, j + 2, k + 9, Blocks.log, 0);
		this.setBlock(world, i + 15, j + 2, k + 15, Blocks.log, 0);
		this.setBlock(world, i + 15, j + 3, k + 1, Blocks.log, 0);
		this.setBlock(world, i + 15, j + 3, k + 3, Blocks.wool, 4);
		this.setBlock(world, i + 15, j + 3, k + 4, Blocks.log, 0);
		this.setBlock(world, i + 15, j + 3, k + 9, Blocks.log, 0);
		this.setBlock(world, i + 15, j + 3, k + 10, Blocks.wool, 4);
		this.setBlock(world, i + 15, j + 3, k + 15, Blocks.log, 0);
		this.setBlock(world, i + 15, j + 4, k + 1, Blocks.log, 4);
		this.setBlock(world, i + 15, j + 4, k + 4, Blocks.wool, 4);
		this.setBlock(world, i + 15, j + 4, k + 5, Blocks.wool, 4);
		this.setBlock(world, i + 15, j + 4, k + 6, Blocks.wool, 4);
		this.setBlock(world, i + 15, j + 4, k + 7, Blocks.wool, 4);
		this.setBlock(world, i + 15, j + 4, k + 8, Blocks.wool, 4);
		this.setBlock(world, i + 15, j + 4, k + 9, Blocks.wool, 4);
		this.setBlock(world, i + 15, j + 4, k + 15, Blocks.log, 4);
		this.setBlock(world, i + 16, j + 0, k + 0, Blocks.planks, 0);
		this.setBlock(world, i + 16, j + 0, k + 1, Blocks.planks, 0);
		this.setBlock(world, i + 16, j + 0, k + 2, Blocks.planks, 0);
		this.setBlock(world, i + 16, j + 0, k + 3, Blocks.planks, 0);
		this.setBlock(world, i + 16, j + 0, k + 4, Blocks.planks, 0);
		this.setBlock(world, i + 16, j + 0, k + 5, Blocks.planks, 0);
		this.setBlock(world, i + 16, j + 0, k + 6, Blocks.planks, 0);
		this.setBlock(world, i + 16, j + 0, k + 7, Blocks.planks, 0);
		this.setBlock(world, i + 16, j + 0, k + 8, Blocks.planks, 0);
		this.setBlock(world, i + 16, j + 0, k + 9, Blocks.planks, 0);
		this.setBlock(world, i + 16, j + 0, k + 10, Blocks.planks, 0);
		this.setBlock(world, i + 16, j + 0, k + 11, Blocks.planks, 0);
		this.setBlock(world, i + 16, j + 0, k + 12, Blocks.planks, 0);
		this.setBlock(world, i + 16, j + 0, k + 13, Blocks.planks, 0);
		this.setBlock(world, i + 16, j + 0, k + 14, Blocks.planks, 0);
		this.setBlock(world, i + 16, j + 0, k + 15, Blocks.planks, 0);
		this.setBlock(world, i + 16, j + 0, k + 16, Blocks.planks, 0);
		this.setBlock(world, i + 16, j + 1, k + 1, Blocks.log, 0);
		this.setBlock(world, i + 16, j + 1, k + 15, Blocks.log, 0);
		this.setBlock(world, i + 16, j + 2, k + 1, Blocks.log, 0);
		this.setBlock(world, i + 16, j + 2, k + 15, Blocks.log, 0);
		this.setBlock(world, i + 16, j + 3, k + 1, Blocks.log, 0);
		this.setBlock(world, i + 16, j + 3, k + 3, Blocks.wool, 4);
		this.setBlock(world, i + 16, j + 3, k + 4, Blocks.wool, 4);
		this.setBlock(world, i + 16, j + 3, k + 5, Blocks.wool, 4);
		this.setBlock(world, i + 16, j + 3, k + 6, Blocks.wool, 4);
		this.setBlock(world, i + 16, j + 3, k + 7, Blocks.wool, 4);
		this.setBlock(world, i + 16, j + 3, k + 8, Blocks.wool, 4);
		this.setBlock(world, i + 16, j + 3, k + 9, Blocks.wool, 4);
		this.setBlock(world, i + 16, j + 3, k + 10, Blocks.wool, 4);
		this.setBlock(world, i + 16, j + 3, k + 15, Blocks.log, 0);
		this.setBlock(world, i + 16, j + 4, k + 1, Blocks.log, 4);
		this.setBlock(world, i + 16, j + 4, k + 15, Blocks.log, 0);
		this.setBlock(world, i + 17, j + 0, k + 0, Blocks.planks, 0);
		this.setBlock(world, i + 17, j + 0, k + 1, Blocks.planks, 0);
		this.setBlock(world, i + 17, j + 0, k + 2, Blocks.planks, 0);
		this.setBlock(world, i + 17, j + 0, k + 3, Blocks.planks, 0);
		this.setBlock(world, i + 17, j + 0, k + 4, Blocks.planks, 0);
		this.setBlock(world, i + 17, j + 0, k + 5, Blocks.planks, 0);
		this.setBlock(world, i + 17, j + 0, k + 6, Blocks.planks, 0);
		this.setBlock(world, i + 17, j + 0, k + 7, Blocks.planks, 0);
		this.setBlock(world, i + 17, j + 0, k + 8, Blocks.planks, 0);
		this.setBlock(world, i + 17, j + 0, k + 9, Blocks.planks, 0);
		this.setBlock(world, i + 17, j + 0, k + 10, Blocks.planks, 0);
		this.setBlock(world, i + 17, j + 0, k + 11, Blocks.planks, 0);
		this.setBlock(world, i + 17, j + 0, k + 12, Blocks.planks, 0);
		this.setBlock(world, i + 17, j + 0, k + 13, Blocks.planks, 0);
		this.setBlock(world, i + 17, j + 0, k + 14, Blocks.planks, 0);
		this.setBlock(world, i + 17, j + 0, k + 15, Blocks.planks, 0);
		this.setBlock(world, i + 17, j + 0, k + 16, Blocks.planks, 0);
		this.setBlock(world, i + 17, j + 1, k + 1, Blocks.log, 0);
		this.setBlock(world, i + 17, j + 1, k + 15, Blocks.log, 0);
		this.setBlock(world, i + 17, j + 2, k + 1, Blocks.log, 0);
		this.setBlock(world, i + 17, j + 2, k + 15, Blocks.log, 0);
		this.setBlock(world, i + 17, j + 3, k + 1, Blocks.log, 0);
		this.setBlock(world, i + 17, j + 3, k + 15, Blocks.log, 0);
		this.setBlock(world, i + 17, j + 4, k + 0, Blocks.log, 0);
		this.setBlock(world, i + 17, j + 4, k + 1, Blocks.log, 0);
		this.setBlock(world, i + 17, j + 4, k + 2, Blocks.log, 0);
		this.setBlock(world, i + 17, j + 4, k + 14, Blocks.log, 0);
		this.setBlock(world, i + 17, j + 4, k + 15, Blocks.log, 0);
		this.setBlock(world, i + 17, j + 4, k + 16, Blocks.log, 0);
		this.setBlock(world, i + 18, j + 0, k + 0, Blocks.planks, 0);
		this.setBlock(world, i + 18, j + 0, k + 1, Blocks.planks, 0);
		this.setBlock(world, i + 18, j + 0, k + 2, Blocks.planks, 0);
		this.setBlock(world, i + 18, j + 0, k + 3, Blocks.planks, 0);
		this.setBlock(world, i + 18, j + 0, k + 4, Blocks.planks, 0);
		this.setBlock(world, i + 18, j + 0, k + 5, Blocks.planks, 0);
		this.setBlock(world, i + 18, j + 0, k + 6, Blocks.planks, 0);
		this.setBlock(world, i + 18, j + 0, k + 7, Blocks.planks, 0);
		this.setBlock(world, i + 18, j + 0, k + 8, Blocks.planks, 0);
		this.setBlock(world, i + 18, j + 0, k + 9, Blocks.planks, 0);
		this.setBlock(world, i + 18, j + 0, k + 10, Blocks.planks, 0);
		this.setBlock(world, i + 18, j + 0, k + 11, Blocks.planks, 0);
		this.setBlock(world, i + 18, j + 0, k + 12, Blocks.planks, 0);
		this.setBlock(world, i + 18, j + 0, k + 13, Blocks.planks, 0);
		this.setBlock(world, i + 18, j + 0, k + 14, Blocks.planks, 0);
		this.setBlock(world, i + 18, j + 0, k + 15, Blocks.planks, 0);
		this.setBlock(world, i + 18, j + 0, k + 16, Blocks.planks, 0);
		this.setBlock(world, i + 18, j + 1, k + 0, Blocks.log, 0);
		this.setBlock(world, i + 18, j + 1, k + 1, Blocks.log, 0);
		this.setBlock(world, i + 18, j + 1, k + 2, Blocks.log, 0);
		this.setBlock(world, i + 18, j + 1, k + 3, Blocks.log, 0);
		this.setBlock(world, i + 18, j + 1, k + 4, Blocks.log, 0);
		this.setBlock(world, i + 18, j + 1, k + 5, Blocks.log, 0);
		this.setBlock(world, i + 18, j + 1, k + 6, Blocks.log, 0);
		this.setBlock(world, i + 18, j + 1, k + 7, Blocks.log, 0);
		this.setBlock(world, i + 18, j + 1, k + 8, Blocks.log, 0);
		this.setBlock(world, i + 18, j + 1, k + 9, Blocks.log, 0);
		this.setBlock(world, i + 18, j + 1, k + 10, Blocks.log, 0);
		this.setBlock(world, i + 18, j + 1, k + 11, Blocks.log, 0);
		this.setBlock(world, i + 18, j + 1, k + 12, Blocks.log, 0);
		this.setBlock(world, i + 18, j + 1, k + 13, Blocks.log, 0);
		this.setBlock(world, i + 18, j + 1, k + 14, Blocks.log, 0);
		this.setBlock(world, i + 18, j + 1, k + 15, Blocks.log, 0);
		this.setBlock(world, i + 18, j + 1, k + 16, Blocks.log, 0);
		this.setBlock(world, i + 18, j + 2, k + 0, Blocks.log, 0);
		this.setBlock(world, i + 18, j + 2, k + 1, Blocks.log, 0);
		this.setBlock(world, i + 18, j + 2, k + 2, Blocks.log, 0);
		this.setBlock(world, i + 18, j + 2, k + 3, Blocks.log, 0);
		this.setBlock(world, i + 18, j + 2, k + 4, Blocks.log, 0);
		this.setBlock(world, i + 18, j + 2, k + 5, Blocks.log, 0);
		this.setBlock(world, i + 18, j + 2, k + 6, Blocks.log, 0);
		this.setBlock(world, i + 18, j + 2, k + 7, Blocks.log, 0);
		this.setBlock(world, i + 18, j + 2, k + 8, Blocks.log, 0);
		this.setBlock(world, i + 18, j + 2, k + 9, Blocks.log, 0);
		this.setBlock(world, i + 18, j + 2, k + 10, Blocks.log, 0);
		this.setBlock(world, i + 18, j + 2, k + 11, Blocks.log, 0);
		this.setBlock(world, i + 18, j + 2, k + 12, Blocks.log, 0);
		this.setBlock(world, i + 18, j + 2, k + 13, Blocks.log, 0);
		this.setBlock(world, i + 18, j + 2, k + 14, Blocks.log, 0);
		this.setBlock(world, i + 18, j + 2, k + 15, Blocks.log, 0);
		this.setBlock(world, i + 18, j + 2, k + 16, Blocks.log, 0);
		this.setBlock(world, i + 18, j + 3, k + 0, Blocks.log, 0);
		this.setBlock(world, i + 18, j + 3, k + 1, Blocks.log, 0);
		this.setBlock(world, i + 18, j + 3, k + 2, Blocks.log, 0);
		this.setBlock(world, i + 18, j + 3, k + 3, Blocks.log, 0);
		this.setBlock(world, i + 18, j + 3, k + 4, Blocks.log, 0);
		this.setBlock(world, i + 18, j + 3, k + 5, Blocks.log, 0);
		this.setBlock(world, i + 18, j + 3, k + 6, Blocks.log, 0);
		this.setBlock(world, i + 18, j + 3, k + 7, Blocks.log, 0);
		this.setBlock(world, i + 18, j + 3, k + 8, Blocks.log, 0);
		this.setBlock(world, i + 18, j + 3, k + 9, Blocks.log, 0);
		this.setBlock(world, i + 18, j + 3, k + 10, Blocks.log, 0);
		this.setBlock(world, i + 18, j + 3, k + 11, Blocks.log, 0);
		this.setBlock(world, i + 18, j + 3, k + 12, Blocks.log, 0);
		this.setBlock(world, i + 18, j + 3, k + 13, Blocks.log, 0);
		this.setBlock(world, i + 18, j + 3, k + 14, Blocks.log, 0);
		this.setBlock(world, i + 18, j + 3, k + 15, Blocks.log, 0);
		this.setBlock(world, i + 18, j + 3, k + 16, Blocks.log, 0);
		this.setBlock(world, i + 18, j + 4, k + 0, Blocks.log, 0);
		this.setBlock(world, i + 18, j + 4, k + 1, Blocks.log, 0);
		this.setBlock(world, i + 18, j + 4, k + 2, Blocks.log, 0);
		this.setBlock(world, i + 18, j + 4, k + 3, Blocks.log, 8);
		this.setBlock(world, i + 18, j + 4, k + 4, Blocks.log, 8);
		this.setBlock(world, i + 18, j + 4, k + 5, Blocks.log, 8);
		this.setBlock(world, i + 18, j + 4, k + 6, Blocks.log, 8);
		this.setBlock(world, i + 18, j + 4, k + 7, Blocks.log, 8);
		this.setBlock(world, i + 18, j + 4, k + 8, Blocks.log, 8);
		this.setBlock(world, i + 18, j + 4, k + 9, Blocks.log, 8);
		this.setBlock(world, i + 18, j + 4, k + 10, Blocks.log, 8);
		this.setBlock(world, i + 18, j + 4, k + 11, Blocks.log, 0);
		this.setBlock(world, i + 18, j + 4, k + 12, Blocks.log, 0);
		this.setBlock(world, i + 18, j + 4, k + 13, Blocks.log, 0);
		this.setBlock(world, i + 18, j + 4, k + 14, Blocks.log, 0);
		this.setBlock(world, i + 18, j + 4, k + 15, Blocks.log, 0);
		this.setBlock(world, i + 18, j + 4, k + 16, Blocks.log, 0);
		this.setBlock(world, i + 19, j + 0, k + 0, Blocks.planks, 0);
		this.setBlock(world, i + 19, j + 0, k + 1, Blocks.planks, 0);
		this.setBlock(world, i + 19, j + 0, k + 2, Blocks.planks, 0);
		this.setBlock(world, i + 19, j + 0, k + 3, Blocks.planks, 0);
		this.setBlock(world, i + 19, j + 0, k + 4, Blocks.planks, 0);
		this.setBlock(world, i + 19, j + 0, k + 5, Blocks.planks, 0);
		this.setBlock(world, i + 19, j + 0, k + 6, Blocks.planks, 0);
		this.setBlock(world, i + 19, j + 0, k + 7, Blocks.planks, 0);
		this.setBlock(world, i + 19, j + 0, k + 8, Blocks.planks, 0);
		this.setBlock(world, i + 19, j + 0, k + 9, Blocks.planks, 0);
		this.setBlock(world, i + 19, j + 0, k + 10, Blocks.planks, 0);
		this.setBlock(world, i + 19, j + 0, k + 11, Blocks.planks, 0);
		this.setBlock(world, i + 19, j + 0, k + 12, Blocks.planks, 0);
		this.setBlock(world, i + 19, j + 0, k + 13, Blocks.planks, 0);
		this.setBlock(world, i + 19, j + 0, k + 14, Blocks.planks, 0);
		this.setBlock(world, i + 19, j + 0, k + 15, Blocks.planks, 0);
		this.setBlock(world, i + 19, j + 0, k + 16, Blocks.planks, 0);
		this.setBlock(world, i + 19, j + 1, k + 1, Blocks.log, 0);
		this.setBlock(world, i + 19, j + 1, k + 15, Blocks.log, 0);
		this.setBlock(world, i + 19, j + 2, k + 1, Blocks.log, 0);
		this.setBlock(world, i + 19, j + 2, k + 15, Blocks.log, 0);
		this.setBlock(world, i + 19, j + 3, k + 1, Blocks.log, 0);
		this.setBlock(world, i + 19, j + 3, k + 15, Blocks.log, 0);
		this.setBlock(world, i + 19, j + 4, k + 0, Blocks.log, 0);
		this.setBlock(world, i + 19, j + 4, k + 1, Blocks.log, 0);
		this.setBlock(world, i + 19, j + 4, k + 2, Blocks.log, 0);
		this.setBlock(world, i + 19, j + 4, k + 14, Blocks.log, 0);
		this.setBlock(world, i + 19, j + 4, k + 15, Blocks.log, 0);
		this.setBlock(world, i + 19, j + 4, k + 16, Blocks.log, 0);
		this.setBlock(world, i + 1, j + 1, k + 7, Blocks.fence_gate, 0);
		this.setBlock(world, i + 1, j + 1, k + 8, Blocks.fence_gate, 0);
		this.setBlock(world, i + 1, j + 1, k + 9, Blocks.fence_gate, 0);
		this.setBlock(world, i + 1, j + 1, k + 10, Blocks.fence_gate, 0);
		world.setBlockMetadataWithNotify(i + 1, j + 2, k + 7, 8, 2);
		world.setBlockMetadataWithNotify(i + 1, j + 2, k + 8, 9, 2);
		world.setBlockMetadataWithNotify(i + 1, j + 2, k + 9, 9, 2);
		world.setBlockMetadataWithNotify(i + 1, j + 2, k + 10, 9, 2);
		world.setBlockMetadataWithNotify(i + 2, j + 2, k + 2, 10, 2);
		world.setBlockMetadataWithNotify(i + 4, j + 2, k + 2, 9, 2);
		world.setBlockMetadataWithNotify(i + 19, j + 1, k + 10, 15, 2);
		world.setBlockMetadataWithNotify(i + 19, j + 2, k + 7, 15, 2);
		world.setBlockMetadataWithNotify(i + 19, j + 4, k + 4, 7, 2);

		return true;
	}
}