/*
*** MADE BjMRPONYCAPTAIN'S .SCHEMATIC TO .JAVA CONVERTING TOOL v2.0 ***
*/

package com.ktreus.minecraftrealms.structures;

import java.util.Random;

import net.minecraft.block.Block;
import net.minecraft.init.Blocks;
import net.minecraft.world.World;
import net.minecraft.world.chunk.IChunkProvider;
import net.minecraft.world.gen.feature.WorldGenerator;

import com.ktreus.minecraftrealms.registers.MRBlocksRegister;
import com.ktreus.minecraftrealms.registers.MRStructuresRegister;

public class MRCastleUrbanLootTST extends WorldGenerator
{
	protected Block[] getValidSpawnBlocks() {
		return new Block[] {
			Blocks.grass
		};
	}

	public boolean locationIsValidSpawn(World world, int i, int j, int k){
		int distanceToAir = 0;
		Block check = world.getBlock(i, j, k);

		while (check != Blocks.air){
			if (distanceToAir > 3){
				return false;
			}

			distanceToAir++;
			check = world.getBlock(i, j + distanceToAir, k);
		}

		j += distanceToAir - 1;

		Block block = world.getBlock(i, j, k);
		Block blockAbove = world.getBlock(i, j+1, k);
		Block blockBelow = world.getBlock(i, j-1, k);
		
		for (Block x: getValidSpawnBlocks()){
			if (blockAbove != Blocks.air){
				return false;
			}
			if (block == x){
				return true;
			}else if (block == Blocks.snow && blockBelow == x){
				return true;
			}
		}
		
		return false;
	}

	public MRCastleUrbanLootTST() {
	
	}

	public void generate(Random random, int chunkX, int chunkZ, World world, IChunkProvider chunkGenerator, IChunkProvider chunkProvider) { }

	public void setBlock(World world, int x, int y, int z, Block block, int metadata)
	{
		Block b1 = world.getBlock(x, y, z);

		if(b1.isAir(world, x, y, z) || b1.isLeaves(world, x, y, z))
		{
			world.setBlock(x, y, z, block, metadata, 2);
		}
	}

	public boolean generate(World world, Random rand, int i, int j, int k) {
		//check that each corner is one of the valid spawn blocks
		

		k = k - 10;
		i = i - 10;

		this.setBlock(world, i + 0, j + 0, k + 7, Blocks.brick_block, 0);
		this.setBlock(world, i + 0, j + 0, k + 8, Blocks.brick_block, 0);
		this.setBlock(world, i + 1, j + 0, k + 7, Blocks.brick_block, 0);
		this.setBlock(world, i + 1, j + 0, k + 8, Blocks.brick_block, 0);
		this.setBlock(world, i + 1, j + 1, k + 0, Blocks.brick_block, 0);
		this.setBlock(world, i + 1, j + 1, k + 1, Blocks.brick_block, 0);
		this.setBlock(world, i + 1, j + 1, k + 2, Blocks.brick_block, 0);
		this.setBlock(world, i + 1, j + 1, k + 3, Blocks.brick_block, 0);
		this.setBlock(world, i + 1, j + 1, k + 4, Blocks.brick_block, 0);
		this.setBlock(world, i + 1, j + 1, k + 5, Blocks.brick_block, 0);
		this.setBlock(world, i + 1, j + 1, k + 6, Blocks.brick_block, 0);
		this.setBlock(world, i + 1, j + 1, k + 7, Blocks.fence_gate, 1);
		this.setBlock(world, i + 1, j + 1, k + 8, Blocks.fence_gate, 1);
		this.setBlock(world, i + 1, j + 1, k + 9, Blocks.brick_block, 0);
		this.setBlock(world, i + 1, j + 1, k + 10, Blocks.brick_block, 0);
		this.setBlock(world, i + 1, j + 1, k + 11, Blocks.brick_block, 0);
		this.setBlock(world, i + 1, j + 1, k + 12, Blocks.brick_block, 0);
		this.setBlock(world, i + 1, j + 1, k + 13, Blocks.brick_block, 0);
		this.setBlock(world, i + 1, j + 1, k + 14, Blocks.brick_block, 0);
		this.setBlock(world, i + 1, j + 1, k + 15, Blocks.brick_block, 0);
		this.setBlock(world, i + 1, j + 2, k + 0, Blocks.brick_block, 0);
		this.setBlock(world, i + 1, j + 2, k + 1, Blocks.brick_block, 0);
		this.setBlock(world, i + 1, j + 2, k + 2, Blocks.brick_block, 0);
		this.setBlock(world, i + 1, j + 2, k + 3, Blocks.brick_block, 0);
		this.setBlock(world, i + 1, j + 2, k + 4, Blocks.brick_block, 0);
		this.setBlock(world, i + 1, j + 2, k + 5, Blocks.brick_block, 0);
		this.setBlock(world, i + 1, j + 2, k + 6, Blocks.brick_block, 0);
		this.setBlock(world, i + 1, j + 2, k + 9, Blocks.brick_block, 0);
		this.setBlock(world, i + 1, j + 2, k + 10, Blocks.brick_block, 0);
		this.setBlock(world, i + 1, j + 2, k + 11, Blocks.brick_block, 0);
		this.setBlock(world, i + 1, j + 2, k + 12, Blocks.brick_block, 0);
		this.setBlock(world, i + 1, j + 2, k + 13, Blocks.brick_block, 0);
		this.setBlock(world, i + 1, j + 2, k + 14, Blocks.brick_block, 0);
		this.setBlock(world, i + 1, j + 2, k + 15, Blocks.brick_block, 0);
		this.setBlock(world, i + 1, j + 3, k + 0, Blocks.brick_block, 0);
		this.setBlock(world, i + 1, j + 3, k + 1, Blocks.brick_block, 0);
		this.setBlock(world, i + 1, j + 3, k + 2, Blocks.brick_block, 0);
		this.setBlock(world, i + 1, j + 3, k + 3, Blocks.brick_block, 0);
		this.setBlock(world, i + 1, j + 3, k + 4, Blocks.brick_block, 0);
		this.setBlock(world, i + 1, j + 3, k + 5, Blocks.brick_block, 0);
		this.setBlock(world, i + 1, j + 3, k + 6, Blocks.brick_block, 0);
		this.setBlock(world, i + 1, j + 3, k + 7, Blocks.brick_block, 0);
		this.setBlock(world, i + 1, j + 3, k + 8, Blocks.brick_block, 0);
		this.setBlock(world, i + 1, j + 3, k + 9, Blocks.brick_block, 0);
		this.setBlock(world, i + 1, j + 3, k + 10, Blocks.brick_block, 0);
		this.setBlock(world, i + 1, j + 3, k + 11, Blocks.brick_block, 0);
		this.setBlock(world, i + 1, j + 3, k + 12, Blocks.brick_block, 0);
		this.setBlock(world, i + 1, j + 3, k + 13, Blocks.brick_block, 0);
		this.setBlock(world, i + 1, j + 3, k + 14, Blocks.brick_block, 0);
		this.setBlock(world, i + 1, j + 3, k + 15, Blocks.brick_block, 0);
		this.setBlock(world, i + 1, j + 4, k + 0, Blocks.brick_block, 0);
		this.setBlock(world, i + 1, j + 4, k + 1, Blocks.brick_block, 0);
		this.setBlock(world, i + 1, j + 4, k + 2, Blocks.brick_block, 0);
		this.setBlock(world, i + 1, j + 4, k + 3, Blocks.brick_block, 0);
		this.setBlock(world, i + 1, j + 4, k + 4, Blocks.brick_block, 0);
		this.setBlock(world, i + 1, j + 4, k + 5, Blocks.brick_block, 0);
		this.setBlock(world, i + 1, j + 4, k + 6, Blocks.brick_block, 0);
		this.setBlock(world, i + 1, j + 4, k + 7, Blocks.brick_block, 0);
		this.setBlock(world, i + 1, j + 4, k + 8, Blocks.brick_block, 0);
		this.setBlock(world, i + 1, j + 4, k + 9, Blocks.brick_block, 0);
		this.setBlock(world, i + 1, j + 4, k + 10, Blocks.brick_block, 0);
		this.setBlock(world, i + 1, j + 4, k + 11, Blocks.brick_block, 0);
		this.setBlock(world, i + 1, j + 4, k + 12, Blocks.brick_block, 0);
		this.setBlock(world, i + 1, j + 4, k + 13, Blocks.brick_block, 0);
		this.setBlock(world, i + 1, j + 4, k + 14, Blocks.brick_block, 0);
		this.setBlock(world, i + 1, j + 4, k + 15, Blocks.brick_block, 0);
		this.setBlock(world, i + 1, j + 5, k + 0, Blocks.brick_block, 0);
		this.setBlock(world, i + 1, j + 5, k + 1, Blocks.iron_bars, 0);
		this.setBlock(world, i + 1, j + 5, k + 2, Blocks.brick_block, 0);
		this.setBlock(world, i + 1, j + 5, k + 3, Blocks.iron_bars, 0);
		this.setBlock(world, i + 1, j + 5, k + 4, Blocks.brick_block, 0);
		this.setBlock(world, i + 1, j + 5, k + 5, Blocks.iron_bars, 0);
		this.setBlock(world, i + 1, j + 5, k + 6, Blocks.brick_block, 0);
		this.setBlock(world, i + 1, j + 5, k + 7, Blocks.iron_bars, 0);
		this.setBlock(world, i + 1, j + 5, k + 8, Blocks.iron_bars, 0);
		this.setBlock(world, i + 1, j + 5, k + 9, Blocks.brick_block, 0);
		this.setBlock(world, i + 1, j + 5, k + 10, Blocks.iron_bars, 0);
		this.setBlock(world, i + 1, j + 5, k + 11, Blocks.brick_block, 0);
		this.setBlock(world, i + 1, j + 5, k + 12, Blocks.iron_bars, 0);
		this.setBlock(world, i + 1, j + 5, k + 13, Blocks.brick_block, 0);
		this.setBlock(world, i + 1, j + 5, k + 14, Blocks.iron_bars, 0);
		this.setBlock(world, i + 1, j + 5, k + 15, Blocks.brick_block, 0);
		this.setBlock(world, i + 2, j + 0, k + 1, Blocks.brick_block, 0);
		this.setBlock(world, i + 2, j + 0, k + 2, Blocks.brick_block, 0);
		this.setBlock(world, i + 2, j + 0, k + 3, Blocks.brick_block, 0);
		this.setBlock(world, i + 2, j + 0, k + 4, Blocks.brick_block, 0);
		this.setBlock(world, i + 2, j + 0, k + 5, Blocks.brick_block, 0);
		this.setBlock(world, i + 2, j + 0, k + 6, Blocks.brick_block, 0);
		this.setBlock(world, i + 2, j + 0, k + 7, Blocks.brick_block, 0);
		this.setBlock(world, i + 2, j + 0, k + 8, Blocks.brick_block, 0);
		this.setBlock(world, i + 2, j + 0, k + 9, Blocks.brick_block, 0);
		this.setBlock(world, i + 2, j + 0, k + 10, Blocks.brick_block, 0);
		this.setBlock(world, i + 2, j + 0, k + 11, Blocks.brick_block, 0);
		this.setBlock(world, i + 2, j + 0, k + 12, Blocks.brick_block, 0);
		this.setBlock(world, i + 2, j + 0, k + 13, Blocks.brick_block, 0);
		this.setBlock(world, i + 2, j + 0, k + 14, Blocks.brick_block, 0);
		this.setBlock(world, i + 2, j + 1, k + 0, Blocks.brick_block, 0);
		this.setBlock(world, i + 2, j + 1, k + 15, Blocks.brick_block, 0);
		this.setBlock(world, i + 2, j + 2, k + 0, Blocks.brick_block, 0);
		this.setBlock(world, i + 2, j + 2, k + 15, Blocks.brick_block, 0);
		this.setBlock(world, i + 2, j + 3, k + 0, Blocks.brick_block, 0);
		this.setBlock(world, i + 2, j + 3, k + 15, Blocks.brick_block, 0);
		this.setBlock(world, i + 2, j + 4, k + 0, Blocks.brick_block, 0);
		this.setBlock(world, i + 2, j + 4, k + 1, Blocks.mossy_cobblestone, 12);
		this.setBlock(world, i + 2, j + 4, k + 2, Blocks.mossy_cobblestone, 12);
		this.setBlock(world, i + 2, j + 4, k + 3, Blocks.mossy_cobblestone, 12);
		this.setBlock(world, i + 2, j + 4, k + 4, Blocks.mossy_cobblestone, 12);
		this.setBlock(world, i + 2, j + 4, k + 5, Blocks.mossy_cobblestone, 12);
		this.setBlock(world, i + 2, j + 4, k + 6, Blocks.mossy_cobblestone, 12);
		this.setBlock(world, i + 2, j + 4, k + 7, Blocks.mossy_cobblestone, 12);
		this.setBlock(world, i + 2, j + 4, k + 8, Blocks.mossy_cobblestone, 12);
		this.setBlock(world, i + 2, j + 4, k + 9, Blocks.mossy_cobblestone, 12);
		this.setBlock(world, i + 2, j + 4, k + 10, Blocks.mossy_cobblestone, 12);
		this.setBlock(world, i + 2, j + 4, k + 11, Blocks.mossy_cobblestone, 12);
		this.setBlock(world, i + 2, j + 4, k + 12, Blocks.mossy_cobblestone, 12);
		this.setBlock(world, i + 2, j + 4, k + 13, Blocks.mossy_cobblestone, 12);
		this.setBlock(world, i + 2, j + 4, k + 14, Blocks.mossy_cobblestone, 12);
		this.setBlock(world, i + 2, j + 4, k + 15, Blocks.brick_block, 0);
		this.setBlock(world, i + 2, j + 5, k + 0, Blocks.iron_bars, 0);
		this.setBlock(world, i + 2, j + 5, k + 15, Blocks.iron_bars, 0);
		this.setBlock(world, i + 3, j + 0, k + 1, Blocks.brick_block, 0);
		this.setBlock(world, i + 3, j + 0, k + 2, Blocks.brick_block, 0);
		this.setBlock(world, i + 3, j + 0, k + 3, Blocks.brick_block, 0);
		this.setBlock(world, i + 3, j + 0, k + 4, Blocks.brick_block, 0);
		this.setBlock(world, i + 3, j + 0, k + 5, Blocks.brick_block, 0);
		this.setBlock(world, i + 3, j + 0, k + 6, Blocks.brick_block, 0);
		this.setBlock(world, i + 3, j + 0, k + 7, Blocks.brick_block, 0);
		this.setBlock(world, i + 3, j + 0, k + 8, Blocks.brick_block, 0);
		this.setBlock(world, i + 3, j + 0, k + 9, Blocks.brick_block, 0);
		this.setBlock(world, i + 3, j + 0, k + 10, Blocks.brick_block, 0);
		this.setBlock(world, i + 3, j + 0, k + 11, Blocks.brick_block, 0);
		this.setBlock(world, i + 3, j + 0, k + 12, Blocks.brick_block, 0);
		this.setBlock(world, i + 3, j + 0, k + 13, Blocks.brick_block, 0);
		this.setBlock(world, i + 3, j + 0, k + 14, Blocks.brick_block, 0);
		this.setBlock(world, i + 3, j + 1, k + 0, Blocks.brick_block, 0);
		this.setBlock(world, i + 3, j + 1, k + 15, Blocks.brick_block, 0);
		this.setBlock(world, i + 3, j + 2, k + 0, Blocks.brick_block, 0);
		this.setBlock(world, i + 3, j + 2, k + 15, Blocks.brick_block, 0);
		this.setBlock(world, i + 3, j + 3, k + 0, Blocks.brick_block, 0);
		this.setBlock(world, i + 3, j + 3, k + 15, Blocks.brick_block, 0);
		this.setBlock(world, i + 3, j + 4, k + 0, Blocks.brick_block, 0);
		this.setBlock(world, i + 3, j + 4, k + 1, Blocks.mossy_cobblestone, 12);
		this.setBlock(world, i + 3, j + 4, k + 2, Blocks.mossy_cobblestone, 12);
		this.setBlock(world, i + 3, j + 4, k + 3, Blocks.mossy_cobblestone, 12);
		this.setBlock(world, i + 3, j + 4, k + 4, Blocks.mossy_cobblestone, 12);
		this.setBlock(world, i + 3, j + 4, k + 5, Blocks.mossy_cobblestone, 12);
		this.setBlock(world, i + 3, j + 4, k + 6, Blocks.mossy_cobblestone, 12);
		this.setBlock(world, i + 3, j + 4, k + 7, Blocks.mossy_cobblestone, 12);
		this.setBlock(world, i + 3, j + 4, k + 8, Blocks.mossy_cobblestone, 12);
		this.setBlock(world, i + 3, j + 4, k + 9, Blocks.mossy_cobblestone, 12);
		this.setBlock(world, i + 3, j + 4, k + 10, Blocks.mossy_cobblestone, 12);
		this.setBlock(world, i + 3, j + 4, k + 11, Blocks.mossy_cobblestone, 12);
		this.setBlock(world, i + 3, j + 4, k + 12, Blocks.mossy_cobblestone, 12);
		this.setBlock(world, i + 3, j + 4, k + 13, Blocks.mossy_cobblestone, 12);
		this.setBlock(world, i + 3, j + 4, k + 14, Blocks.mossy_cobblestone, 12);
		this.setBlock(world, i + 3, j + 4, k + 15, Blocks.brick_block, 0);
		this.setBlock(world, i + 3, j + 5, k + 0, Blocks.brick_block, 0);
		this.setBlock(world, i + 3, j + 5, k + 2, Blocks.iron_bars, 0);
		this.setBlock(world, i + 3, j + 5, k + 3, Blocks.iron_bars, 0);
		this.setBlock(world, i + 3, j + 5, k + 4, Blocks.iron_bars, 0);
		this.setBlock(world, i + 3, j + 5, k + 5, Blocks.iron_bars, 0);
		this.setBlock(world, i + 3, j + 5, k + 6, Blocks.iron_bars, 0);
		this.setBlock(world, i + 3, j + 5, k + 7, Blocks.iron_bars, 0);
		this.setBlock(world, i + 3, j + 5, k + 8, Blocks.iron_bars, 0);
		this.setBlock(world, i + 3, j + 5, k + 9, Blocks.iron_bars, 0);
		this.setBlock(world, i + 3, j + 5, k + 10, Blocks.iron_bars, 0);
		this.setBlock(world, i + 3, j + 5, k + 11, Blocks.iron_bars, 0);
		this.setBlock(world, i + 3, j + 5, k + 12, Blocks.iron_bars, 0);
		this.setBlock(world, i + 3, j + 5, k + 13, Blocks.iron_bars, 0);
		this.setBlock(world, i + 3, j + 5, k + 15, Blocks.brick_block, 0);
		this.setBlock(world, i + 4, j + 0, k + 1, Blocks.brick_block, 0);
		this.setBlock(world, i + 4, j + 0, k + 2, Blocks.brick_block, 0);
		this.setBlock(world, i + 4, j + 0, k + 3, Blocks.brick_block, 0);
		this.setBlock(world, i + 4, j + 0, k + 4, Blocks.brick_block, 0);
		this.setBlock(world, i + 4, j + 0, k + 5, Blocks.brick_block, 0);
		this.setBlock(world, i + 4, j + 0, k + 6, Blocks.brick_block, 0);
		this.setBlock(world, i + 4, j + 0, k + 7, Blocks.brick_block, 0);
		this.setBlock(world, i + 4, j + 0, k + 8, Blocks.brick_block, 0);
		this.setBlock(world, i + 4, j + 0, k + 9, Blocks.brick_block, 0);
		this.setBlock(world, i + 4, j + 0, k + 10, Blocks.brick_block, 0);
		this.setBlock(world, i + 4, j + 0, k + 11, Blocks.brick_block, 0);
		this.setBlock(world, i + 4, j + 0, k + 12, Blocks.brick_block, 0);
		this.setBlock(world, i + 4, j + 0, k + 13, Blocks.brick_block, 0);
		this.setBlock(world, i + 4, j + 0, k + 14, Blocks.brick_block, 0);
		this.setBlock(world, i + 4, j + 1, k + 0, Blocks.brick_block, 0);
		this.setBlock(world, i + 4, j + 1, k + 15, Blocks.brick_block, 0);
		this.setBlock(world, i + 4, j + 2, k + 0, Blocks.brick_block, 0);
		this.setBlock(world, i + 4, j + 2, k + 15, Blocks.brick_block, 0);
		this.setBlock(world, i + 4, j + 3, k + 0, Blocks.brick_block, 0);
		this.setBlock(world, i + 4, j + 3, k + 15, Blocks.brick_block, 0);
		this.setBlock(world, i + 4, j + 4, k + 0, Blocks.brick_block, 0);
		this.setBlock(world, i + 4, j + 4, k + 1, Blocks.mossy_cobblestone, 12);
		this.setBlock(world, i + 4, j + 4, k + 2, Blocks.mossy_cobblestone, 12);
		this.setBlock(world, i + 4, j + 4, k + 13, Blocks.mossy_cobblestone, 12);
		this.setBlock(world, i + 4, j + 4, k + 14, Blocks.mossy_cobblestone, 12);
		this.setBlock(world, i + 4, j + 4, k + 15, Blocks.brick_block, 0);
		this.setBlock(world, i + 4, j + 5, k + 0, Blocks.iron_bars, 0);
		this.setBlock(world, i + 4, j + 5, k + 2, Blocks.iron_bars, 0);
		this.setBlock(world, i + 4, j + 5, k + 8, MRStructuresRegister.monsterSpawnBlock, 0);
		this.setBlock(world, i + 4, j + 5, k + 13, Blocks.iron_bars, 0);
		this.setBlock(world, i + 4, j + 5, k + 15, Blocks.iron_bars, 0);
		this.setBlock(world, i + 5, j + 0, k + 1, Blocks.brick_block, 0);
		this.setBlock(world, i + 5, j + 0, k + 2, Blocks.brick_block, 0);
		this.setBlock(world, i + 5, j + 0, k + 3, Blocks.brick_block, 0);
		this.setBlock(world, i + 5, j + 0, k + 7, Blocks.brick_block, 0);
		this.setBlock(world, i + 5, j + 0, k + 12, Blocks.brick_block, 0);
		this.setBlock(world, i + 5, j + 0, k + 13, Blocks.brick_block, 0);
		this.setBlock(world, i + 5, j + 0, k + 14, Blocks.brick_block, 0);
		this.setBlock(world, i + 5, j + 1, k + 0, Blocks.brick_block, 0);
		this.setBlock(world, i + 5, j + 1, k + 4, Blocks.brick_block, 0);
		this.setBlock(world, i + 5, j + 1, k + 5, Blocks.brick_block, 0);
		this.setBlock(world, i + 5, j + 1, k + 6, Blocks.brick_block, 0);
		this.setBlock(world, i + 5, j + 1, k + 7, Blocks.fence_gate, 3);
		this.setBlock(world, i + 5, j + 1, k + 8, Blocks.brick_block, 0);
		this.setBlock(world, i + 5, j + 1, k + 9, Blocks.brick_block, 0);
		this.setBlock(world, i + 5, j + 1, k + 10, Blocks.brick_block, 0);
		this.setBlock(world, i + 5, j + 1, k + 11, Blocks.brick_block, 0);
		this.setBlock(world, i + 5, j + 1, k + 15, Blocks.brick_block, 0);
		this.setBlock(world, i + 5, j + 2, k + 0, Blocks.brick_block, 0);
		this.setBlock(world, i + 5, j + 2, k + 4, Blocks.brick_block, 0);
		this.setBlock(world, i + 5, j + 2, k + 5, Blocks.brick_block, 0);
		this.setBlock(world, i + 5, j + 2, k + 6, Blocks.brick_block, 0);
		this.setBlock(world, i + 5, j + 2, k + 8, Blocks.brick_block, 0);
		this.setBlock(world, i + 5, j + 2, k + 9, Blocks.brick_block, 0);
		this.setBlock(world, i + 5, j + 2, k + 10, Blocks.brick_block, 0);
		this.setBlock(world, i + 5, j + 2, k + 11, Blocks.brick_block, 0);
		this.setBlock(world, i + 5, j + 2, k + 15, Blocks.brick_block, 0);
		this.setBlock(world, i + 5, j + 3, k + 0, Blocks.brick_block, 0);
		this.setBlock(world, i + 5, j + 3, k + 4, Blocks.brick_block, 0);
		this.setBlock(world, i + 5, j + 3, k + 5, Blocks.brick_block, 0);
		this.setBlock(world, i + 5, j + 3, k + 6, Blocks.brick_block, 0);
		this.setBlock(world, i + 5, j + 3, k + 7, Blocks.brick_block, 0);
		this.setBlock(world, i + 5, j + 3, k + 8, Blocks.brick_block, 0);
		this.setBlock(world, i + 5, j + 3, k + 9, Blocks.brick_block, 0);
		this.setBlock(world, i + 5, j + 3, k + 10, Blocks.brick_block, 0);
		this.setBlock(world, i + 5, j + 3, k + 11, Blocks.brick_block, 0);
		this.setBlock(world, i + 5, j + 3, k + 15, Blocks.brick_block, 0);
		this.setBlock(world, i + 5, j + 4, k + 0, Blocks.brick_block, 0);
		this.setBlock(world, i + 5, j + 4, k + 1, Blocks.mossy_cobblestone, 12);
		this.setBlock(world, i + 5, j + 4, k + 2, Blocks.mossy_cobblestone, 12);
		this.setBlock(world, i + 5, j + 4, k + 4, Blocks.brick_block, 0);
		this.setBlock(world, i + 5, j + 4, k + 5, Blocks.brick_block, 0);
		this.setBlock(world, i + 5, j + 4, k + 6, Blocks.brick_block, 0);
		this.setBlock(world, i + 5, j + 4, k + 7, Blocks.brick_block, 0);
		this.setBlock(world, i + 5, j + 4, k + 8, Blocks.brick_block, 0);
		this.setBlock(world, i + 5, j + 4, k + 9, Blocks.brick_block, 0);
		this.setBlock(world, i + 5, j + 4, k + 10, Blocks.brick_block, 0);
		this.setBlock(world, i + 5, j + 4, k + 11, Blocks.brick_block, 0);
		this.setBlock(world, i + 5, j + 4, k + 13, Blocks.mossy_cobblestone, 12);
		this.setBlock(world, i + 5, j + 4, k + 14, Blocks.mossy_cobblestone, 12);
		this.setBlock(world, i + 5, j + 4, k + 15, Blocks.brick_block, 0);
		this.setBlock(world, i + 5, j + 5, k + 0, Blocks.brick_block, 0);
		this.setBlock(world, i + 5, j + 5, k + 2, Blocks.iron_bars, 0);
		this.setBlock(world, i + 5, j + 5, k + 4, Blocks.brick_block, 0);
		this.setBlock(world, i + 5, j + 5, k + 5, Blocks.brick_block, 0);
		this.setBlock(world, i + 5, j + 5, k + 6, Blocks.brick_block, 0);
		this.setBlock(world, i + 5, j + 5, k + 7, Blocks.brick_block, 0);
		this.setBlock(world, i + 5, j + 5, k + 8, Blocks.brick_block, 0);
		this.setBlock(world, i + 5, j + 5, k + 9, Blocks.brick_block, 0);
		this.setBlock(world, i + 5, j + 5, k + 10, Blocks.brick_block, 0);
		this.setBlock(world, i + 5, j + 5, k + 11, Blocks.brick_block, 0);
		this.setBlock(world, i + 5, j + 5, k + 13, Blocks.iron_bars, 0);
		this.setBlock(world, i + 5, j + 5, k + 15, Blocks.brick_block, 0);
		this.setBlock(world, i + 5, j + 6, k + 4, Blocks.brick_block, 0);
		this.setBlock(world, i + 5, j + 6, k + 5, Blocks.brick_block, 0);
		this.setBlock(world, i + 5, j + 6, k + 6, Blocks.glass_pane, 0);
		this.setBlock(world, i + 5, j + 6, k + 7, Blocks.brick_block, 0);
		this.setBlock(world, i + 5, j + 6, k + 8, Blocks.brick_block, 0);
		this.setBlock(world, i + 5, j + 6, k + 9, Blocks.glass_pane, 0);
		this.setBlock(world, i + 5, j + 6, k + 10, Blocks.brick_block, 0);
		this.setBlock(world, i + 5, j + 6, k + 11, Blocks.brick_block, 0);
		this.setBlock(world, i + 5, j + 7, k + 4, Blocks.brick_block, 0);
		this.setBlock(world, i + 5, j + 7, k + 5, Blocks.brick_block, 0);
		this.setBlock(world, i + 5, j + 7, k + 6, Blocks.brick_stairs, 5);
		this.setBlock(world, i + 5, j + 7, k + 7, Blocks.brick_block, 0);
		this.setBlock(world, i + 5, j + 7, k + 8, Blocks.brick_block, 0);
		this.setBlock(world, i + 5, j + 7, k + 9, Blocks.brick_stairs, 5);
		this.setBlock(world, i + 5, j + 7, k + 10, Blocks.brick_block, 0);
		this.setBlock(world, i + 5, j + 7, k + 11, Blocks.brick_block, 0);
		this.setBlock(world, i + 5, j + 8, k + 4, Blocks.brick_block, 0);
		this.setBlock(world, i + 5, j + 8, k + 5, Blocks.brick_block, 0);
		this.setBlock(world, i + 5, j + 8, k + 6, Blocks.brick_block, 0);
		this.setBlock(world, i + 5, j + 8, k + 7, Blocks.brick_block, 0);
		this.setBlock(world, i + 5, j + 8, k + 8, Blocks.brick_block, 0);
		this.setBlock(world, i + 5, j + 8, k + 9, Blocks.brick_block, 0);
		this.setBlock(world, i + 5, j + 8, k + 10, Blocks.brick_block, 0);
		this.setBlock(world, i + 5, j + 8, k + 11, Blocks.brick_block, 0);
		this.setBlock(world, i + 5, j + 9, k + 4, Blocks.brick_block, 0);
		this.setBlock(world, i + 5, j + 9, k + 6, Blocks.brick_block, 0);
		this.setBlock(world, i + 5, j + 9, k + 9, Blocks.brick_block, 0);
		this.setBlock(world, i + 5, j + 9, k + 11, Blocks.brick_block, 0);
		this.setBlock(world, i + 6, j + 0, k + 1, Blocks.brick_block, 0);
		this.setBlock(world, i + 6, j + 0, k + 2, Blocks.brick_block, 0);
		this.setBlock(world, i + 6, j + 0, k + 3, Blocks.brick_block, 0);
		this.setBlock(world, i + 6, j + 0, k + 5, Blocks.air, 5);
		this.setBlock(world, i + 6, j + 0, k + 6, Blocks.air, 5);
		this.setBlock(world, i + 6, j + 0, k + 7, Blocks.air, 5);
		this.setBlock(world, i + 6, j + 0, k + 8, Blocks.air, 5);
		this.setBlock(world, i + 6, j + 0, k + 9, Blocks.air, 5);
		this.setBlock(world, i + 6, j + 0, k + 10, Blocks.air, 5);
		this.setBlock(world, i + 6, j + 0, k + 12, Blocks.brick_block, 0);
		this.setBlock(world, i + 6, j + 0, k + 13, Blocks.brick_block, 0);
		this.setBlock(world, i + 6, j + 0, k + 14, Blocks.brick_block, 0);
		this.setBlock(world, i + 6, j + 1, k + 0, Blocks.brick_block, 0);
		this.setBlock(world, i + 6, j + 1, k + 4, Blocks.brick_block, 0);
		this.setBlock(world, i + 6, j + 1, k + 9, Blocks.mossy_cobblestone, 4);
		this.setBlock(world, i + 6, j + 1, k + 10, Blocks.brick_stairs, 0);
		this.setBlock(world, i + 6, j + 1, k + 11, Blocks.brick_block, 0);
		this.setBlock(world, i + 6, j + 1, k + 15, Blocks.brick_block, 0);
		this.setBlock(world, i + 6, j + 2, k + 0, Blocks.brick_block, 0);
		this.setBlock(world, i + 6, j + 2, k + 4, Blocks.brick_block, 0);
		this.setBlock(world, i + 6, j + 2, k + 11, Blocks.brick_block, 0);
		this.setBlock(world, i + 6, j + 2, k + 15, Blocks.brick_block, 0);
		this.setBlock(world, i + 6, j + 3, k + 0, Blocks.brick_block, 0);
		this.setBlock(world, i + 6, j + 3, k + 4, Blocks.brick_block, 0);
		this.setBlock(world, i + 6, j + 3, k + 11, Blocks.brick_block, 0);
		this.setBlock(world, i + 6, j + 3, k + 15, Blocks.brick_block, 0);
		this.setBlock(world, i + 6, j + 4, k + 0, Blocks.brick_block, 0);
		this.setBlock(world, i + 6, j + 4, k + 1, Blocks.mossy_cobblestone, 12);
		this.setBlock(world, i + 6, j + 4, k + 2, Blocks.mossy_cobblestone, 12);
		this.setBlock(world, i + 6, j + 4, k + 4, Blocks.brick_block, 0);
		this.setBlock(world, i + 6, j + 4, k + 5, Blocks.mossy_cobblestone, 12);
		this.setBlock(world, i + 6, j + 4, k + 6, Blocks.mossy_cobblestone, 12);
		this.setBlock(world, i + 6, j + 4, k + 7, Blocks.mossy_cobblestone, 12);
		this.setBlock(world, i + 6, j + 4, k + 8, Blocks.mossy_cobblestone, 12);
		this.setBlock(world, i + 6, j + 4, k + 9, Blocks.mossy_cobblestone, 12);
		this.setBlock(world, i + 6, j + 4, k + 11, Blocks.brick_block, 0);
		this.setBlock(world, i + 6, j + 4, k + 13, Blocks.mossy_cobblestone, 12);
		this.setBlock(world, i + 6, j + 4, k + 14, Blocks.mossy_cobblestone, 12);
		this.setBlock(world, i + 6, j + 4, k + 15, Blocks.brick_block, 0);
		this.setBlock(world, i + 6, j + 5, k + 0, Blocks.iron_bars, 0);
		this.setBlock(world, i + 6, j + 5, k + 2, Blocks.iron_bars, 0);
		this.setBlock(world, i + 6, j + 5, k + 4, Blocks.brick_block, 0);
		this.setBlock(world, i + 6, j + 5, k + 11, Blocks.brick_block, 0);
		this.setBlock(world, i + 6, j + 5, k + 13, Blocks.iron_bars, 0);
		this.setBlock(world, i + 6, j + 5, k + 15, Blocks.iron_bars, 0);
		this.setBlock(world, i + 6, j + 6, k + 4, Blocks.brick_block, 0);
		this.setBlock(world, i + 6, j + 6, k + 11, Blocks.brick_block, 0);
		this.setBlock(world, i + 6, j + 7, k + 4, Blocks.brick_block, 0);
		this.setBlock(world, i + 6, j + 7, k + 5, Blocks.mossy_cobblestone, 12);
		this.setBlock(world, i + 6, j + 7, k + 6, Blocks.mossy_cobblestone, 12);
		this.setBlock(world, i + 6, j + 7, k + 7, Blocks.mossy_cobblestone, 12);
		this.setBlock(world, i + 6, j + 7, k + 8, Blocks.mossy_cobblestone, 12);
		this.setBlock(world, i + 6, j + 7, k + 9, Blocks.mossy_cobblestone, 12);
		this.setBlock(world, i + 6, j + 7, k + 10, Blocks.mossy_cobblestone, 12);
		this.setBlock(world, i + 6, j + 7, k + 11, Blocks.brick_block, 0);
		this.setBlock(world, i + 6, j + 8, k + 4, Blocks.brick_block, 0);
		this.setBlock(world, i + 6, j + 8, k + 11, Blocks.brick_block, 0);
		this.setBlock(world, i + 7, j + 0, k + 1, Blocks.brick_block, 0);
		this.setBlock(world, i + 7, j + 0, k + 2, Blocks.brick_block, 0);
		this.setBlock(world, i + 7, j + 0, k + 3, Blocks.brick_block, 0);
		this.setBlock(world, i + 7, j + 0, k + 5, Blocks.air, 5);
		this.setBlock(world, i + 7, j + 0, k + 6, Blocks.air, 5);
		this.setBlock(world, i + 7, j + 0, k + 7, Blocks.air, 5);
		this.setBlock(world, i + 7, j + 0, k + 8, Blocks.air, 5);
		this.setBlock(world, i + 7, j + 0, k + 9, Blocks.air, 5);
		this.setBlock(world, i + 7, j + 0, k + 10, Blocks.air, 5);
		this.setBlock(world, i + 7, j + 0, k + 12, Blocks.brick_block, 0);
		this.setBlock(world, i + 7, j + 0, k + 13, Blocks.brick_block, 0);
		this.setBlock(world, i + 7, j + 0, k + 14, Blocks.brick_block, 0);
		this.setBlock(world, i + 7, j + 1, k + 0, Blocks.brick_block, 0);
		this.setBlock(world, i + 7, j + 1, k + 4, Blocks.brick_block, 0);
		this.setBlock(world, i + 7, j + 1, k + 10, MRBlocksRegister.crate01, 2);
		this.setBlock(world, i + 7, j + 1, k + 11, Blocks.brick_block, 0);
		this.setBlock(world, i + 7, j + 1, k + 15, Blocks.brick_block, 0);
		this.setBlock(world, i + 7, j + 2, k + 0, Blocks.brick_block, 0);
		this.setBlock(world, i + 7, j + 2, k + 4, Blocks.brick_block, 0);
		this.setBlock(world, i + 7, j + 2, k + 10, Blocks.brick_stairs, 0);
		this.setBlock(world, i + 7, j + 2, k + 11, Blocks.brick_block, 0);
		this.setBlock(world, i + 7, j + 2, k + 15, Blocks.brick_block, 0);
		this.setBlock(world, i + 7, j + 3, k + 0, Blocks.brick_block, 0);
		this.setBlock(world, i + 7, j + 3, k + 4, Blocks.brick_block, 0);
		this.setBlock(world, i + 7, j + 3, k + 11, Blocks.brick_block, 0);
		this.setBlock(world, i + 7, j + 3, k + 15, Blocks.brick_block, 0);
		this.setBlock(world, i + 7, j + 4, k + 0, Blocks.brick_block, 0);
		this.setBlock(world, i + 7, j + 4, k + 1, Blocks.mossy_cobblestone, 12);
		this.setBlock(world, i + 7, j + 4, k + 2, Blocks.mossy_cobblestone, 12);
		this.setBlock(world, i + 7, j + 4, k + 4, Blocks.brick_block, 0);
		this.setBlock(world, i + 7, j + 4, k + 5, Blocks.mossy_cobblestone, 12);
		this.setBlock(world, i + 7, j + 4, k + 6, Blocks.mossy_cobblestone, 12);
		this.setBlock(world, i + 7, j + 4, k + 7, Blocks.mossy_cobblestone, 12);
		this.setBlock(world, i + 7, j + 4, k + 8, Blocks.mossy_cobblestone, 12);
		this.setBlock(world, i + 7, j + 4, k + 9, Blocks.mossy_cobblestone, 12);
		this.setBlock(world, i + 7, j + 4, k + 11, Blocks.brick_block, 0);
		this.setBlock(world, i + 7, j + 4, k + 13, Blocks.mossy_cobblestone, 12);
		this.setBlock(world, i + 7, j + 4, k + 14, Blocks.mossy_cobblestone, 12);
		this.setBlock(world, i + 7, j + 4, k + 15, Blocks.brick_block, 0);
		this.setBlock(world, i + 7, j + 5, k + 0, Blocks.brick_block, 0);
		this.setBlock(world, i + 7, j + 5, k + 2, Blocks.iron_bars, 0);
		this.setBlock(world, i + 7, j + 5, k + 4, Blocks.brick_block, 0);
		this.setBlock(world, i + 7, j + 5, k + 11, Blocks.brick_block, 0);
		this.setBlock(world, i + 7, j + 5, k + 13, Blocks.iron_bars, 0);
		this.setBlock(world, i + 7, j + 5, k + 15, Blocks.brick_block, 0);
		this.setBlock(world, i + 7, j + 6, k + 4, Blocks.glass_pane, 0);
		this.setBlock(world, i + 7, j + 6, k + 11, Blocks.glass_pane, 0);
		this.setBlock(world, i + 7, j + 7, k + 4, Blocks.brick_stairs, 7);
		this.setBlock(world, i + 7, j + 7, k + 5, Blocks.mossy_cobblestone, 12);
		this.setBlock(world, i + 7, j + 7, k + 6, Blocks.mossy_cobblestone, 12);
		this.setBlock(world, i + 7, j + 7, k + 7, Blocks.mossy_cobblestone, 12);
		this.setBlock(world, i + 7, j + 7, k + 8, Blocks.mossy_cobblestone, 12);
		this.setBlock(world, i + 7, j + 7, k + 9, Blocks.mossy_cobblestone, 12);
		this.setBlock(world, i + 7, j + 7, k + 10, Blocks.mossy_cobblestone, 12);
		this.setBlock(world, i + 7, j + 7, k + 11, Blocks.brick_stairs, 6);
		this.setBlock(world, i + 7, j + 8, k + 4, Blocks.brick_block, 0);
		this.setBlock(world, i + 7, j + 8, k + 10, MRBlocksRegister.crate01, 2);
		this.setBlock(world, i + 7, j + 8, k + 11, Blocks.brick_block, 0);
		this.setBlock(world, i + 7, j + 9, k + 4, Blocks.brick_block, 0);
		this.setBlock(world, i + 7, j + 9, k + 11, Blocks.brick_block, 0);
		this.setBlock(world, i + 8, j + 0, k + 1, Blocks.brick_block, 0);
		this.setBlock(world, i + 8, j + 0, k + 2, Blocks.brick_block, 0);
		this.setBlock(world, i + 8, j + 0, k + 3, Blocks.brick_block, 0);
		this.setBlock(world, i + 8, j + 0, k + 5, Blocks.air, 5);
		this.setBlock(world, i + 8, j + 0, k + 6, Blocks.air, 5);
		this.setBlock(world, i + 8, j + 0, k + 7, Blocks.air, 5);
		this.setBlock(world, i + 8, j + 0, k + 8, Blocks.air, 5);
		this.setBlock(world, i + 8, j + 0, k + 9, Blocks.air, 5);
		this.setBlock(world, i + 8, j + 0, k + 10, Blocks.air, 5);
		this.setBlock(world, i + 8, j + 0, k + 12, Blocks.brick_block, 0);
		this.setBlock(world, i + 8, j + 0, k + 13, Blocks.brick_block, 0);
		this.setBlock(world, i + 8, j + 0, k + 14, Blocks.brick_block, 4);
		this.setBlock(world, i + 8, j + 1, k + 0, Blocks.brick_block, 0);
		this.setBlock(world, i + 8, j + 1, k + 4, Blocks.brick_block, 0);
		this.setBlock(world, i + 8, j + 1, k + 10, Blocks.brick_block, 0);
		this.setBlock(world, i + 8, j + 1, k + 11, Blocks.brick_block, 0);
		this.setBlock(world, i + 8, j + 1, k + 15, Blocks.brick_block, 0);
		this.setBlock(world, i + 8, j + 2, k + 0, Blocks.brick_block, 0);
		this.setBlock(world, i + 8, j + 2, k + 4, Blocks.brick_block, 0);
		this.setBlock(world, i + 8, j + 2, k + 10, Blocks.brick_block, 0);
		this.setBlock(world, i + 8, j + 2, k + 11, Blocks.brick_block, 0);
		this.setBlock(world, i + 8, j + 2, k + 15, Blocks.brick_block, 0);
		this.setBlock(world, i + 8, j + 3, k + 0, Blocks.brick_block, 0);
		this.setBlock(world, i + 8, j + 3, k + 4, Blocks.brick_block, 0);
		this.setBlock(world, i + 8, j + 3, k + 10, Blocks.brick_stairs, 0);
		this.setBlock(world, i + 8, j + 3, k + 11, Blocks.brick_block, 0);
		this.setBlock(world, i + 8, j + 3, k + 15, Blocks.brick_block, 0);
		this.setBlock(world, i + 8, j + 4, k + 0, Blocks.brick_block, 0);
		this.setBlock(world, i + 8, j + 4, k + 1, Blocks.mossy_cobblestone, 12);
		this.setBlock(world, i + 8, j + 4, k + 2, Blocks.mossy_cobblestone, 12);
		this.setBlock(world, i + 8, j + 4, k + 4, Blocks.brick_block, 0);
		this.setBlock(world, i + 8, j + 4, k + 5, Blocks.mossy_cobblestone, 12);
		this.setBlock(world, i + 8, j + 4, k + 6, Blocks.mossy_cobblestone, 12);
		this.setBlock(world, i + 8, j + 4, k + 7, Blocks.mossy_cobblestone, 12);
		this.setBlock(world, i + 8, j + 4, k + 8, Blocks.mossy_cobblestone, 12);
		this.setBlock(world, i + 8, j + 4, k + 9, Blocks.mossy_cobblestone, 12);
		this.setBlock(world, i + 8, j + 4, k + 11, Blocks.brick_block, 0);
		this.setBlock(world, i + 8, j + 4, k + 13, Blocks.mossy_cobblestone, 12);
		this.setBlock(world, i + 8, j + 4, k + 14, Blocks.mossy_cobblestone, 12);
		this.setBlock(world, i + 8, j + 4, k + 15, Blocks.brick_block, 0);
		this.setBlock(world, i + 8, j + 5, k + 0, Blocks.iron_bars, 0);
		this.setBlock(world, i + 8, j + 5, k + 2, Blocks.iron_bars, 0);
		this.setBlock(world, i + 8, j + 5, k + 4, Blocks.brick_block, 0);
		this.setBlock(world, i + 8, j + 5, k + 5, MRBlocksRegister.crate01, 3);
		this.setBlock(world, i + 8, j + 5, k + 11, Blocks.brick_block, 0);
		this.setBlock(world, i + 8, j + 5, k + 13, Blocks.iron_bars, 0);
		this.setBlock(world, i + 8, j + 5, k + 15, Blocks.iron_bars, 0);
		this.setBlock(world, i + 8, j + 6, k + 4, Blocks.brick_block, 0);
		this.setBlock(world, i + 8, j + 6, k + 11, Blocks.brick_block, 0);
		this.setBlock(world, i + 8, j + 7, k + 4, Blocks.brick_block, 0);
		this.setBlock(world, i + 8, j + 7, k + 5, Blocks.brick_stairs, 1);
		this.setBlock(world, i + 8, j + 7, k + 6, Blocks.mossy_cobblestone, 12);
		this.setBlock(world, i + 8, j + 7, k + 7, Blocks.mossy_cobblestone, 12);
		this.setBlock(world, i + 8, j + 7, k + 8, Blocks.mossy_cobblestone, 12);
		this.setBlock(world, i + 8, j + 7, k + 9, Blocks.mossy_cobblestone, 12);
		this.setBlock(world, i + 8, j + 7, k + 10, Blocks.mossy_cobblestone, 12);
		this.setBlock(world, i + 8, j + 7, k + 11, Blocks.brick_block, 0);
		this.setBlock(world, i + 8, j + 8, k + 4, Blocks.brick_block, 0);
		this.setBlock(world, i + 8, j + 8, k + 8, MRStructuresRegister.monsterSpawnBlock, 0);
		this.setBlock(world, i + 8, j + 8, k + 11, Blocks.brick_block, 0);
		this.setBlock(world, i + 9, j + 0, k + 1, Blocks.brick_block, 0);
		this.setBlock(world, i + 9, j + 0, k + 2, Blocks.brick_block, 0);
		this.setBlock(world, i + 9, j + 0, k + 3, Blocks.brick_block, 0);
		this.setBlock(world, i + 9, j + 0, k + 5, Blocks.air, 5);
		this.setBlock(world, i + 9, j + 0, k + 6, Blocks.air, 5);
		this.setBlock(world, i + 9, j + 0, k + 7, Blocks.air, 5);
		this.setBlock(world, i + 9, j + 0, k + 8, Blocks.air, 5);
		this.setBlock(world, i + 9, j + 0, k + 9, Blocks.air, 5);
		this.setBlock(world, i + 9, j + 0, k + 10, Blocks.air, 5);
		this.setBlock(world, i + 9, j + 0, k + 12, Blocks.brick_block, 0);
		this.setBlock(world, i + 9, j + 0, k + 13, Blocks.brick_block, 0);
		this.setBlock(world, i + 9, j + 0, k + 14, Blocks.brick_block, 0);
		this.setBlock(world, i + 9, j + 1, k + 0, Blocks.brick_block, 0);
		this.setBlock(world, i + 9, j + 1, k + 4, Blocks.brick_block, 0);
		this.setBlock(world, i + 9, j + 1, k + 7, MRStructuresRegister.monsterSpawnBlock, 0);
		this.setBlock(world, i + 9, j + 1, k + 11, Blocks.brick_block, 0);
		this.setBlock(world, i + 9, j + 1, k + 15, Blocks.brick_block, 0);
		this.setBlock(world, i + 9, j + 2, k + 0, Blocks.brick_block, 0);
		this.setBlock(world, i + 9, j + 2, k + 4, Blocks.brick_block, 0);
		this.setBlock(world, i + 9, j + 2, k + 11, Blocks.brick_block, 0);
		this.setBlock(world, i + 9, j + 2, k + 15, Blocks.brick_block, 0);
		this.setBlock(world, i + 9, j + 3, k + 0, Blocks.brick_block, 0);
		this.setBlock(world, i + 9, j + 3, k + 4, Blocks.brick_block, 0);
		this.setBlock(world, i + 9, j + 3, k + 11, Blocks.brick_block, 0);
		this.setBlock(world, i + 9, j + 3, k + 15, Blocks.brick_block, 0);
		this.setBlock(world, i + 9, j + 4, k + 0, Blocks.brick_block, 0);
		this.setBlock(world, i + 9, j + 4, k + 1, Blocks.mossy_cobblestone, 12);
		this.setBlock(world, i + 9, j + 4, k + 2, Blocks.mossy_cobblestone, 12);
		this.setBlock(world, i + 9, j + 4, k + 4, Blocks.brick_block, 0);
		this.setBlock(world, i + 9, j + 4, k + 5, Blocks.mossy_cobblestone, 12);
		this.setBlock(world, i + 9, j + 4, k + 6, Blocks.mossy_cobblestone, 12);
		this.setBlock(world, i + 9, j + 4, k + 7, Blocks.mossy_cobblestone, 12);
		this.setBlock(world, i + 9, j + 4, k + 8, Blocks.mossy_cobblestone, 12);
		this.setBlock(world, i + 9, j + 4, k + 9, Blocks.mossy_cobblestone, 12);
		this.setBlock(world, i + 9, j + 4, k + 10, Blocks.brick_stairs, 0);
		this.setBlock(world, i + 9, j + 4, k + 11, Blocks.brick_block, 0);
		this.setBlock(world, i + 9, j + 4, k + 13, Blocks.mossy_cobblestone, 12);
		this.setBlock(world, i + 9, j + 4, k + 14, Blocks.mossy_cobblestone, 12);
		this.setBlock(world, i + 9, j + 4, k + 15, Blocks.brick_block, 0);
		this.setBlock(world, i + 9, j + 5, k + 0, Blocks.brick_block, 0);
		this.setBlock(world, i + 9, j + 5, k + 2, Blocks.iron_bars, 0);
		this.setBlock(world, i + 9, j + 5, k + 4, Blocks.brick_block, 0);
		this.setBlock(world, i + 9, j + 5, k + 5, Blocks.brick_block, 0);
		this.setBlock(world, i + 9, j + 5, k + 11, Blocks.brick_block, 0);
		this.setBlock(world, i + 9, j + 5, k + 13, Blocks.iron_bars, 0);
		this.setBlock(world, i + 9, j + 5, k + 15, Blocks.brick_block, 0);
		this.setBlock(world, i + 9, j + 6, k + 4, Blocks.brick_block, 0);
		this.setBlock(world, i + 9, j + 6, k + 5, Blocks.brick_stairs, 1);
		this.setBlock(world, i + 9, j + 6, k + 11, Blocks.glass_pane, 0);
		this.setBlock(world, i + 9, j + 7, k + 4, Blocks.brick_stairs, 7);
		this.setBlock(world, i + 9, j + 7, k + 6, Blocks.mossy_cobblestone, 12);
		this.setBlock(world, i + 9, j + 7, k + 7, Blocks.mossy_cobblestone, 12);
		this.setBlock(world, i + 9, j + 7, k + 8, Blocks.mossy_cobblestone, 12);
		this.setBlock(world, i + 9, j + 7, k + 9, Blocks.mossy_cobblestone, 12);
		this.setBlock(world, i + 9, j + 7, k + 10, Blocks.mossy_cobblestone, 12);
		this.setBlock(world, i + 9, j + 7, k + 11, Blocks.brick_stairs, 6);
		this.setBlock(world, i + 9, j + 8, k + 4, Blocks.brick_block, 0);
		this.setBlock(world, i + 9, j + 8, k + 11, Blocks.brick_block, 0);
		this.setBlock(world, i + 9, j + 9, k + 4, Blocks.brick_block, 0);
		this.setBlock(world, i + 9, j + 9, k + 11, Blocks.brick_block, 0);
		this.setBlock(world, i + 10, j + 0, k + 1, Blocks.brick_block, 0);
		this.setBlock(world, i + 10, j + 0, k + 2, Blocks.brick_block, 0);
		this.setBlock(world, i + 10, j + 0, k + 3, Blocks.brick_block, 0);
		this.setBlock(world, i + 10, j + 0, k + 5, Blocks.air, 5);
		this.setBlock(world, i + 10, j + 0, k + 6, Blocks.air, 5);
		this.setBlock(world, i + 10, j + 0, k + 7, Blocks.air, 5);
		this.setBlock(world, i + 10, j + 0, k + 8, Blocks.air, 5);
		this.setBlock(world, i + 10, j + 0, k + 9, Blocks.air, 5);
		this.setBlock(world, i + 10, j + 0, k + 10, Blocks.air, 5);
		this.setBlock(world, i + 10, j + 0, k + 12, Blocks.brick_block, 0);
		this.setBlock(world, i + 10, j + 0, k + 13, Blocks.brick_block, 0);
		this.setBlock(world, i + 10, j + 0, k + 14, Blocks.brick_block, 0);
		this.setBlock(world, i + 10, j + 1, k + 0, Blocks.brick_block, 0);
		this.setBlock(world, i + 10, j + 1, k + 4, Blocks.brick_block, 0);
		this.setBlock(world, i + 10, j + 1, k + 11, Blocks.brick_block, 0);
		this.setBlock(world, i + 10, j + 1, k + 15, Blocks.brick_block, 0);
		this.setBlock(world, i + 10, j + 2, k + 0, Blocks.brick_block, 0);
		this.setBlock(world, i + 10, j + 2, k + 4, Blocks.brick_block, 0);
		this.setBlock(world, i + 10, j + 2, k + 11, Blocks.brick_block, 0);
		this.setBlock(world, i + 10, j + 2, k + 15, Blocks.brick_block, 0);
		this.setBlock(world, i + 10, j + 3, k + 0, Blocks.brick_block, 0);
		this.setBlock(world, i + 10, j + 3, k + 4, Blocks.brick_block, 0);
		this.setBlock(world, i + 10, j + 3, k + 11, Blocks.brick_block, 0);
		this.setBlock(world, i + 10, j + 3, k + 15, Blocks.brick_block, 0);
		this.setBlock(world, i + 10, j + 4, k + 0, Blocks.brick_block, 0);
		this.setBlock(world, i + 10, j + 4, k + 1, Blocks.mossy_cobblestone, 12);
		this.setBlock(world, i + 10, j + 4, k + 2, Blocks.mossy_cobblestone, 12);
		this.setBlock(world, i + 10, j + 4, k + 4, Blocks.brick_block, 0);
		this.setBlock(world, i + 10, j + 4, k + 5, Blocks.mossy_cobblestone, 12);
		this.setBlock(world, i + 10, j + 4, k + 6, Blocks.mossy_cobblestone, 12);
		this.setBlock(world, i + 10, j + 4, k + 7, Blocks.mossy_cobblestone, 12);
		this.setBlock(world, i + 10, j + 4, k + 8, Blocks.mossy_cobblestone, 12);
		this.setBlock(world, i + 10, j + 4, k + 9, Blocks.mossy_cobblestone, 12);
		this.setBlock(world, i + 10, j + 4, k + 10, Blocks.mossy_cobblestone, 12);
		this.setBlock(world, i + 10, j + 4, k + 11, Blocks.brick_block, 0);
		this.setBlock(world, i + 10, j + 4, k + 13, Blocks.mossy_cobblestone, 12);
		this.setBlock(world, i + 10, j + 4, k + 14, Blocks.mossy_cobblestone, 12);
		this.setBlock(world, i + 10, j + 4, k + 15, Blocks.brick_block, 0);
		this.setBlock(world, i + 10, j + 5, k + 0, Blocks.iron_bars, 0);
		this.setBlock(world, i + 10, j + 5, k + 2, Blocks.iron_bars, 0);
		this.setBlock(world, i + 10, j + 5, k + 4, Blocks.brick_block, 0);
		this.setBlock(world, i + 10, j + 5, k + 5, Blocks.brick_stairs, 1);
		this.setBlock(world, i + 10, j + 5, k + 6, Blocks.mossy_cobblestone, 4);
		this.setBlock(world, i + 10, j + 5, k + 11, Blocks.brick_block, 0);
		this.setBlock(world, i + 10, j + 5, k + 13, Blocks.iron_bars, 0);
		this.setBlock(world, i + 10, j + 5, k + 15, Blocks.iron_bars, 0);
		this.setBlock(world, i + 10, j + 6, k + 4, Blocks.brick_block, 0);
		this.setBlock(world, i + 10, j + 6, k + 11, Blocks.brick_block, 0);
		this.setBlock(world, i + 10, j + 7, k + 4, Blocks.brick_block, 0);
		this.setBlock(world, i + 10, j + 7, k + 7, Blocks.mossy_cobblestone, 12);
		this.setBlock(world, i + 10, j + 7, k + 8, Blocks.mossy_cobblestone, 12);
		this.setBlock(world, i + 10, j + 7, k + 9, Blocks.mossy_cobblestone, 12);
		this.setBlock(world, i + 10, j + 7, k + 10, Blocks.mossy_cobblestone, 12);
		this.setBlock(world, i + 10, j + 7, k + 11, Blocks.brick_block, 0);
		this.setBlock(world, i + 10, j + 8, k + 4, Blocks.brick_block, 0);
		this.setBlock(world, i + 10, j + 8, k + 11, Blocks.brick_block, 0);
		this.setBlock(world, i + 11, j + 0, k + 1, Blocks.brick_block, 0);
		this.setBlock(world, i + 11, j + 0, k + 2, Blocks.brick_block, 0);
		this.setBlock(world, i + 11, j + 0, k + 3, Blocks.brick_block, 0);
		this.setBlock(world, i + 11, j + 0, k + 12, Blocks.brick_block, 0);
		this.setBlock(world, i + 11, j + 0, k + 13, Blocks.brick_block, 0);
		this.setBlock(world, i + 11, j + 0, k + 14, Blocks.brick_block, 0);
		this.setBlock(world, i + 11, j + 1, k + 0, Blocks.brick_block, 0);
		this.setBlock(world, i + 11, j + 1, k + 4, Blocks.brick_block, 0);
		this.setBlock(world, i + 11, j + 1, k + 5, Blocks.brick_block, 0);
		this.setBlock(world, i + 11, j + 1, k + 6, Blocks.brick_block, 0);
		this.setBlock(world, i + 11, j + 1, k + 7, Blocks.brick_block, 0);
		this.setBlock(world, i + 11, j + 1, k + 8, Blocks.brick_block, 0);
		this.setBlock(world, i + 11, j + 1, k + 9, Blocks.brick_block, 0);
		this.setBlock(world, i + 11, j + 1, k + 10, Blocks.brick_block, 0);
		this.setBlock(world, i + 11, j + 1, k + 11, Blocks.brick_block, 0);
		this.setBlock(world, i + 11, j + 1, k + 15, Blocks.brick_block, 0);
		this.setBlock(world, i + 11, j + 2, k + 0, Blocks.brick_block, 0);
		this.setBlock(world, i + 11, j + 2, k + 4, Blocks.brick_block, 0);
		this.setBlock(world, i + 11, j + 2, k + 5, Blocks.brick_block, 0);
		this.setBlock(world, i + 11, j + 2, k + 6, Blocks.brick_block, 0);
		this.setBlock(world, i + 11, j + 2, k + 7, Blocks.brick_block, 0);
		this.setBlock(world, i + 11, j + 2, k + 8, Blocks.brick_block, 0);
		this.setBlock(world, i + 11, j + 2, k + 9, Blocks.brick_block, 0);
		this.setBlock(world, i + 11, j + 2, k + 10, Blocks.brick_block, 0);
		this.setBlock(world, i + 11, j + 2, k + 11, Blocks.brick_block, 0);
		this.setBlock(world, i + 11, j + 2, k + 15, Blocks.brick_block, 0);
		this.setBlock(world, i + 11, j + 3, k + 0, Blocks.brick_block, 0);
		this.setBlock(world, i + 11, j + 3, k + 4, Blocks.brick_block, 0);
		this.setBlock(world, i + 11, j + 3, k + 5, Blocks.brick_block, 0);
		this.setBlock(world, i + 11, j + 3, k + 6, Blocks.brick_block, 0);
		this.setBlock(world, i + 11, j + 3, k + 7, Blocks.brick_block, 0);
		this.setBlock(world, i + 11, j + 3, k + 8, Blocks.brick_block, 0);
		this.setBlock(world, i + 11, j + 3, k + 9, Blocks.brick_block, 0);
		this.setBlock(world, i + 11, j + 3, k + 10, Blocks.brick_block, 0);
		this.setBlock(world, i + 11, j + 3, k + 11, Blocks.brick_block, 0);
		this.setBlock(world, i + 11, j + 3, k + 15, Blocks.brick_block, 0);
		this.setBlock(world, i + 11, j + 4, k + 0, Blocks.brick_block, 0);
		this.setBlock(world, i + 11, j + 4, k + 1, Blocks.mossy_cobblestone, 12);
		this.setBlock(world, i + 11, j + 4, k + 2, Blocks.mossy_cobblestone, 12);
		this.setBlock(world, i + 11, j + 4, k + 4, Blocks.brick_block, 0);
		this.setBlock(world, i + 11, j + 4, k + 5, Blocks.brick_block, 0);
		this.setBlock(world, i + 11, j + 4, k + 6, Blocks.brick_block, 0);
		this.setBlock(world, i + 11, j + 4, k + 7, Blocks.brick_block, 0);
		this.setBlock(world, i + 11, j + 4, k + 8, Blocks.brick_block, 0);
		this.setBlock(world, i + 11, j + 4, k + 9, Blocks.brick_block, 0);
		this.setBlock(world, i + 11, j + 4, k + 10, Blocks.brick_block, 0);
		this.setBlock(world, i + 11, j + 4, k + 11, Blocks.brick_block, 0);
		this.setBlock(world, i + 11, j + 4, k + 13, Blocks.mossy_cobblestone, 12);
		this.setBlock(world, i + 11, j + 4, k + 14, Blocks.mossy_cobblestone, 12);
		this.setBlock(world, i + 11, j + 4, k + 15, Blocks.brick_block, 0);
		this.setBlock(world, i + 11, j + 5, k + 0, Blocks.brick_block, 0);
		this.setBlock(world, i + 11, j + 5, k + 2, Blocks.iron_bars, 0);
		this.setBlock(world, i + 11, j + 5, k + 4, Blocks.brick_block, 0);
		this.setBlock(world, i + 11, j + 5, k + 5, Blocks.brick_block, 0);
		this.setBlock(world, i + 11, j + 5, k + 6, Blocks.brick_block, 0);
		this.setBlock(world, i + 11, j + 5, k + 7, Blocks.brick_block, 0);
		this.setBlock(world, i + 11, j + 5, k + 8, Blocks.brick_block, 0);
		this.setBlock(world, i + 11, j + 5, k + 9, Blocks.brick_block, 0);
		this.setBlock(world, i + 11, j + 5, k + 10, Blocks.brick_block, 0);
		this.setBlock(world, i + 11, j + 5, k + 11, Blocks.brick_block, 0);
		this.setBlock(world, i + 11, j + 5, k + 13, Blocks.iron_bars, 0);
		this.setBlock(world, i + 11, j + 5, k + 15, Blocks.brick_block, 0);
		this.setBlock(world, i + 11, j + 6, k + 4, Blocks.brick_block, 0);
		this.setBlock(world, i + 11, j + 6, k + 5, Blocks.brick_block, 0);
		this.setBlock(world, i + 11, j + 6, k + 6, Blocks.glass_pane, 0);
		this.setBlock(world, i + 11, j + 6, k + 7, Blocks.brick_block, 0);
		this.setBlock(world, i + 11, j + 6, k + 8, Blocks.brick_block, 0);
		this.setBlock(world, i + 11, j + 6, k + 9, Blocks.glass_pane, 0);
		this.setBlock(world, i + 11, j + 6, k + 10, Blocks.brick_block, 0);
		this.setBlock(world, i + 11, j + 6, k + 11, Blocks.brick_block, 0);
		this.setBlock(world, i + 11, j + 7, k + 4, Blocks.brick_block, 0);
		this.setBlock(world, i + 11, j + 7, k + 5, Blocks.brick_block, 0);
		this.setBlock(world, i + 11, j + 7, k + 6, Blocks.brick_stairs, 4);
		this.setBlock(world, i + 11, j + 7, k + 7, Blocks.brick_block, 0);
		this.setBlock(world, i + 11, j + 7, k + 8, Blocks.brick_block, 0);
		this.setBlock(world, i + 11, j + 7, k + 9, Blocks.brick_stairs, 4);
		this.setBlock(world, i + 11, j + 7, k + 10, Blocks.brick_block, 0);
		this.setBlock(world, i + 11, j + 7, k + 11, Blocks.brick_block, 0);
		this.setBlock(world, i + 11, j + 8, k + 4, Blocks.brick_block, 0);
		this.setBlock(world, i + 11, j + 8, k + 5, Blocks.brick_block, 0);
		this.setBlock(world, i + 11, j + 8, k + 6, Blocks.brick_block, 0);
		this.setBlock(world, i + 11, j + 8, k + 7, Blocks.brick_block, 0);
		this.setBlock(world, i + 11, j + 8, k + 8, Blocks.brick_block, 0);
		this.setBlock(world, i + 11, j + 8, k + 9, Blocks.brick_block, 0);
		this.setBlock(world, i + 11, j + 8, k + 10, Blocks.brick_block, 0);
		this.setBlock(world, i + 11, j + 8, k + 11, Blocks.brick_block, 0);
		this.setBlock(world, i + 11, j + 9, k + 4, Blocks.brick_block, 0);
		this.setBlock(world, i + 11, j + 9, k + 6, Blocks.brick_block, 0);
		this.setBlock(world, i + 11, j + 9, k + 9, Blocks.brick_block, 0);
		this.setBlock(world, i + 11, j + 9, k + 11, Blocks.brick_block, 0);
		this.setBlock(world, i + 12, j + 0, k + 1, Blocks.brick_block, 0);
		this.setBlock(world, i + 12, j + 0, k + 2, Blocks.brick_block, 0);
		this.setBlock(world, i + 12, j + 0, k + 3, Blocks.brick_block, 0);
		this.setBlock(world, i + 12, j + 0, k + 4, Blocks.brick_block, 0);
		this.setBlock(world, i + 12, j + 0, k + 5, Blocks.brick_block, 0);
		this.setBlock(world, i + 12, j + 0, k + 6, Blocks.brick_block, 0);
		this.setBlock(world, i + 12, j + 0, k + 7, Blocks.brick_block, 0);
		this.setBlock(world, i + 12, j + 0, k + 8, Blocks.brick_block, 0);
		this.setBlock(world, i + 12, j + 0, k + 9, Blocks.brick_block, 0);
		this.setBlock(world, i + 12, j + 0, k + 10, Blocks.brick_block, 0);
		this.setBlock(world, i + 12, j + 0, k + 11, Blocks.brick_block, 0);
		this.setBlock(world, i + 12, j + 0, k + 12, Blocks.brick_block, 0);
		this.setBlock(world, i + 12, j + 0, k + 13, Blocks.brick_block, 0);
		this.setBlock(world, i + 12, j + 0, k + 14, Blocks.brick_block, 0);
		this.setBlock(world, i + 12, j + 1, k + 0, Blocks.brick_block, 0);
		this.setBlock(world, i + 12, j + 1, k + 15, Blocks.brick_block, 0);
		this.setBlock(world, i + 12, j + 2, k + 0, Blocks.brick_block, 0);
		this.setBlock(world, i + 12, j + 2, k + 15, Blocks.brick_block, 0);
		this.setBlock(world, i + 12, j + 3, k + 0, Blocks.brick_block, 0);
		this.setBlock(world, i + 12, j + 3, k + 15, Blocks.brick_block, 0);
		this.setBlock(world, i + 12, j + 4, k + 0, Blocks.brick_block, 0);
		this.setBlock(world, i + 12, j + 4, k + 1, Blocks.mossy_cobblestone, 12);
		this.setBlock(world, i + 12, j + 4, k + 2, Blocks.mossy_cobblestone, 12);
		this.setBlock(world, i + 12, j + 4, k + 13, Blocks.mossy_cobblestone, 12);
		this.setBlock(world, i + 12, j + 4, k + 14, Blocks.mossy_cobblestone, 12);
		this.setBlock(world, i + 12, j + 4, k + 15, Blocks.brick_block, 0);
		this.setBlock(world, i + 12, j + 5, k + 0, Blocks.iron_bars, 0);
		this.setBlock(world, i + 12, j + 5, k + 2, Blocks.iron_bars, 0);
		this.setBlock(world, i + 12, j + 5, k + 13, Blocks.iron_bars, 0);
		this.setBlock(world, i + 12, j + 5, k + 15, Blocks.iron_bars, 0);
		this.setBlock(world, i + 13, j + 0, k + 1, Blocks.brick_block, 0);
		this.setBlock(world, i + 13, j + 0, k + 2, Blocks.brick_block, 0);
		this.setBlock(world, i + 13, j + 0, k + 3, Blocks.brick_block, 0);
		this.setBlock(world, i + 13, j + 0, k + 4, Blocks.brick_block, 0);
		this.setBlock(world, i + 13, j + 0, k + 5, Blocks.brick_block, 0);
		this.setBlock(world, i + 13, j + 0, k + 6, Blocks.brick_block, 0);
		this.setBlock(world, i + 13, j + 0, k + 7, Blocks.brick_block, 0);
		this.setBlock(world, i + 13, j + 0, k + 8, Blocks.brick_block, 0);
		this.setBlock(world, i + 13, j + 0, k + 9, Blocks.brick_block, 0);
		this.setBlock(world, i + 13, j + 0, k + 10, Blocks.brick_block, 0);
		this.setBlock(world, i + 13, j + 0, k + 11, Blocks.brick_block, 0);
		this.setBlock(world, i + 13, j + 0, k + 12, Blocks.brick_block, 0);
		this.setBlock(world, i + 13, j + 0, k + 13, Blocks.brick_block, 0);
		this.setBlock(world, i + 13, j + 0, k + 14, Blocks.brick_block, 0);
		this.setBlock(world, i + 13, j + 1, k + 0, Blocks.brick_block, 0);
		this.setBlock(world, i + 13, j + 1, k + 15, Blocks.brick_block, 0);
		this.setBlock(world, i + 13, j + 2, k + 0, Blocks.brick_block, 0);
		this.setBlock(world, i + 13, j + 2, k + 15, Blocks.brick_block, 0);
		this.setBlock(world, i + 13, j + 3, k + 0, Blocks.brick_block, 0);
		this.setBlock(world, i + 13, j + 3, k + 15, Blocks.brick_block, 0);
		this.setBlock(world, i + 13, j + 4, k + 0, Blocks.brick_block, 0);
		this.setBlock(world, i + 13, j + 4, k + 1, Blocks.mossy_cobblestone, 12);
		this.setBlock(world, i + 13, j + 4, k + 2, Blocks.mossy_cobblestone, 12);
		this.setBlock(world, i + 13, j + 4, k + 3, Blocks.mossy_cobblestone, 12);
		this.setBlock(world, i + 13, j + 4, k + 4, Blocks.mossy_cobblestone, 12);
		this.setBlock(world, i + 13, j + 4, k + 5, Blocks.mossy_cobblestone, 12);
		this.setBlock(world, i + 13, j + 4, k + 6, Blocks.mossy_cobblestone, 12);
		this.setBlock(world, i + 13, j + 4, k + 7, Blocks.mossy_cobblestone, 12);
		this.setBlock(world, i + 13, j + 4, k + 8, Blocks.mossy_cobblestone, 12);
		this.setBlock(world, i + 13, j + 4, k + 9, Blocks.mossy_cobblestone, 12);
		this.setBlock(world, i + 13, j + 4, k + 10, Blocks.mossy_cobblestone, 12);
		this.setBlock(world, i + 13, j + 4, k + 11, Blocks.mossy_cobblestone, 12);
		this.setBlock(world, i + 13, j + 4, k + 12, Blocks.mossy_cobblestone, 12);
		this.setBlock(world, i + 13, j + 4, k + 13, Blocks.mossy_cobblestone, 12);
		this.setBlock(world, i + 13, j + 4, k + 14, Blocks.mossy_cobblestone, 12);
		this.setBlock(world, i + 13, j + 4, k + 15, Blocks.brick_block, 0);
		this.setBlock(world, i + 13, j + 5, k + 0, Blocks.brick_block, 0);
		this.setBlock(world, i + 13, j + 5, k + 2, Blocks.iron_bars, 0);
		this.setBlock(world, i + 13, j + 5, k + 3, Blocks.iron_bars, 0);
		this.setBlock(world, i + 13, j + 5, k + 4, Blocks.iron_bars, 0);
		this.setBlock(world, i + 13, j + 5, k + 5, Blocks.iron_bars, 0);
		this.setBlock(world, i + 13, j + 5, k + 6, Blocks.iron_bars, 0);
		this.setBlock(world, i + 13, j + 5, k + 7, Blocks.iron_bars, 0);
		this.setBlock(world, i + 13, j + 5, k + 8, Blocks.iron_bars, 0);
		this.setBlock(world, i + 13, j + 5, k + 9, Blocks.iron_bars, 0);
		this.setBlock(world, i + 13, j + 5, k + 10, Blocks.iron_bars, 0);
		this.setBlock(world, i + 13, j + 5, k + 11, Blocks.iron_bars, 0);
		this.setBlock(world, i + 13, j + 5, k + 12, Blocks.iron_bars, 0);
		this.setBlock(world, i + 13, j + 5, k + 13, Blocks.iron_bars, 0);
		this.setBlock(world, i + 13, j + 5, k + 15, Blocks.brick_block, 0);
		this.setBlock(world, i + 13, j + 6, k + 14, MRStructuresRegister.monsterSpawnBlock, 0);
		this.setBlock(world, i + 14, j + 0, k + 1, Blocks.brick_block, 0);
		this.setBlock(world, i + 14, j + 0, k + 2, Blocks.brick_block, 0);
		this.setBlock(world, i + 14, j + 0, k + 3, Blocks.brick_block, 0);
		this.setBlock(world, i + 14, j + 0, k + 4, Blocks.brick_block, 0);
		this.setBlock(world, i + 14, j + 0, k + 5, Blocks.brick_block, 0);
		this.setBlock(world, i + 14, j + 0, k + 6, Blocks.brick_block, 0);
		this.setBlock(world, i + 14, j + 0, k + 7, Blocks.brick_block, 0);
		this.setBlock(world, i + 14, j + 0, k + 8, Blocks.brick_block, 0);
		this.setBlock(world, i + 14, j + 0, k + 9, Blocks.brick_block, 0);
		this.setBlock(world, i + 14, j + 0, k + 10, Blocks.brick_block, 0);
		this.setBlock(world, i + 14, j + 0, k + 11, Blocks.brick_block, 0);
		this.setBlock(world, i + 14, j + 0, k + 12, Blocks.brick_block, 0);
		this.setBlock(world, i + 14, j + 0, k + 13, Blocks.brick_block, 0);
		this.setBlock(world, i + 14, j + 0, k + 14, Blocks.brick_block, 0);
		this.setBlock(world, i + 14, j + 1, k + 0, Blocks.brick_block, 0);
		this.setBlock(world, i + 14, j + 1, k + 15, Blocks.brick_block, 0);
		this.setBlock(world, i + 14, j + 2, k + 0, Blocks.brick_block, 0);
		this.setBlock(world, i + 14, j + 2, k + 15, Blocks.brick_block, 0);
		this.setBlock(world, i + 14, j + 3, k + 0, Blocks.brick_block, 0);
		this.setBlock(world, i + 14, j + 3, k + 15, Blocks.brick_block, 0);
		this.setBlock(world, i + 14, j + 4, k + 0, Blocks.brick_block, 0);
		this.setBlock(world, i + 14, j + 4, k + 1, Blocks.mossy_cobblestone, 12);
		this.setBlock(world, i + 14, j + 4, k + 2, Blocks.mossy_cobblestone, 12);
		this.setBlock(world, i + 14, j + 4, k + 3, Blocks.mossy_cobblestone, 12);
		this.setBlock(world, i + 14, j + 4, k + 4, Blocks.mossy_cobblestone, 12);
		this.setBlock(world, i + 14, j + 4, k + 5, Blocks.mossy_cobblestone, 12);
		this.setBlock(world, i + 14, j + 4, k + 6, Blocks.mossy_cobblestone, 12);
		this.setBlock(world, i + 14, j + 4, k + 7, Blocks.mossy_cobblestone, 12);
		this.setBlock(world, i + 14, j + 4, k + 8, Blocks.mossy_cobblestone, 12);
		this.setBlock(world, i + 14, j + 4, k + 9, Blocks.mossy_cobblestone, 12);
		this.setBlock(world, i + 14, j + 4, k + 10, Blocks.mossy_cobblestone, 12);
		this.setBlock(world, i + 14, j + 4, k + 11, Blocks.mossy_cobblestone, 12);
		this.setBlock(world, i + 14, j + 4, k + 12, Blocks.mossy_cobblestone, 12);
		this.setBlock(world, i + 14, j + 4, k + 13, Blocks.mossy_cobblestone, 12);
		this.setBlock(world, i + 14, j + 4, k + 14, Blocks.mossy_cobblestone, 12);
		this.setBlock(world, i + 14, j + 4, k + 15, Blocks.brick_block, 0);
		this.setBlock(world, i + 14, j + 5, k + 0, Blocks.iron_bars, 0);
		this.setBlock(world, i + 14, j + 5, k + 15, Blocks.iron_bars, 0);
		this.setBlock(world, i + 15, j + 1, k + 0, Blocks.brick_block, 0);
		this.setBlock(world, i + 15, j + 1, k + 1, Blocks.brick_block, 0);
		this.setBlock(world, i + 15, j + 1, k + 2, Blocks.brick_block, 0);
		this.setBlock(world, i + 15, j + 1, k + 3, Blocks.brick_block, 0);
		this.setBlock(world, i + 15, j + 1, k + 4, Blocks.brick_block, 0);
		this.setBlock(world, i + 15, j + 1, k + 5, Blocks.brick_block, 0);
		this.setBlock(world, i + 15, j + 1, k + 6, Blocks.brick_block, 0);
		this.setBlock(world, i + 15, j + 1, k + 7, Blocks.brick_block, 0);
		this.setBlock(world, i + 15, j + 1, k + 8, Blocks.brick_block, 0);
		this.setBlock(world, i + 15, j + 1, k + 9, Blocks.brick_block, 0);
		this.setBlock(world, i + 15, j + 1, k + 10, Blocks.brick_block, 0);
		this.setBlock(world, i + 15, j + 1, k + 11, Blocks.brick_block, 0);
		this.setBlock(world, i + 15, j + 1, k + 12, Blocks.brick_block, 0);
		this.setBlock(world, i + 15, j + 1, k + 13, Blocks.brick_block, 0);
		this.setBlock(world, i + 15, j + 1, k + 14, Blocks.brick_block, 0);
		this.setBlock(world, i + 15, j + 1, k + 15, Blocks.brick_block, 0);
		this.setBlock(world, i + 15, j + 2, k + 0, Blocks.brick_block, 0);
		this.setBlock(world, i + 15, j + 2, k + 1, Blocks.brick_block, 0);
		this.setBlock(world, i + 15, j + 2, k + 2, Blocks.brick_block, 0);
		this.setBlock(world, i + 15, j + 2, k + 3, Blocks.brick_block, 0);
		this.setBlock(world, i + 15, j + 2, k + 4, Blocks.brick_block, 0);
		this.setBlock(world, i + 15, j + 2, k + 5, Blocks.brick_block, 0);
		this.setBlock(world, i + 15, j + 2, k + 6, Blocks.brick_block, 0);
		this.setBlock(world, i + 15, j + 2, k + 7, Blocks.brick_block, 0);
		this.setBlock(world, i + 15, j + 2, k + 8, Blocks.brick_block, 0);
		this.setBlock(world, i + 15, j + 2, k + 9, Blocks.brick_block, 0);
		this.setBlock(world, i + 15, j + 2, k + 10, Blocks.brick_block, 0);
		this.setBlock(world, i + 15, j + 2, k + 11, Blocks.brick_block, 0);
		this.setBlock(world, i + 15, j + 2, k + 12, Blocks.brick_block, 0);
		this.setBlock(world, i + 15, j + 2, k + 13, Blocks.brick_block, 0);
		this.setBlock(world, i + 15, j + 2, k + 14, Blocks.brick_block, 0);
		this.setBlock(world, i + 15, j + 2, k + 15, Blocks.brick_block, 0);
		this.setBlock(world, i + 15, j + 3, k + 0, Blocks.brick_block, 0);
		this.setBlock(world, i + 15, j + 3, k + 1, Blocks.brick_block, 0);
		this.setBlock(world, i + 15, j + 3, k + 2, Blocks.brick_block, 0);
		this.setBlock(world, i + 15, j + 3, k + 3, Blocks.brick_block, 0);
		this.setBlock(world, i + 15, j + 3, k + 4, Blocks.brick_block, 0);
		this.setBlock(world, i + 15, j + 3, k + 5, Blocks.brick_block, 0);
		this.setBlock(world, i + 15, j + 3, k + 6, Blocks.brick_block, 0);
		this.setBlock(world, i + 15, j + 3, k + 7, Blocks.brick_block, 0);
		this.setBlock(world, i + 15, j + 3, k + 8, Blocks.brick_block, 0);
		this.setBlock(world, i + 15, j + 3, k + 9, Blocks.brick_block, 0);
		this.setBlock(world, i + 15, j + 3, k + 10, Blocks.brick_block, 0);
		this.setBlock(world, i + 15, j + 3, k + 11, Blocks.brick_block, 0);
		this.setBlock(world, i + 15, j + 3, k + 12, Blocks.brick_block, 0);
		this.setBlock(world, i + 15, j + 3, k + 13, Blocks.brick_block, 0);
		this.setBlock(world, i + 15, j + 3, k + 14, Blocks.brick_block, 0);
		this.setBlock(world, i + 15, j + 3, k + 15, Blocks.brick_block, 0);
		this.setBlock(world, i + 15, j + 4, k + 0, Blocks.brick_block, 0);
		this.setBlock(world, i + 15, j + 4, k + 1, Blocks.brick_block, 0);
		this.setBlock(world, i + 15, j + 4, k + 2, Blocks.brick_block, 0);
		this.setBlock(world, i + 15, j + 4, k + 3, Blocks.brick_block, 0);
		this.setBlock(world, i + 15, j + 4, k + 4, Blocks.brick_block, 0);
		this.setBlock(world, i + 15, j + 4, k + 5, Blocks.brick_block, 0);
		this.setBlock(world, i + 15, j + 4, k + 6, Blocks.brick_block, 0);
		this.setBlock(world, i + 15, j + 4, k + 7, Blocks.brick_block, 0);
		this.setBlock(world, i + 15, j + 4, k + 8, Blocks.brick_block, 0);
		this.setBlock(world, i + 15, j + 4, k + 9, Blocks.brick_block, 0);
		this.setBlock(world, i + 15, j + 4, k + 10, Blocks.brick_block, 0);
		this.setBlock(world, i + 15, j + 4, k + 11, Blocks.brick_block, 0);
		this.setBlock(world, i + 15, j + 4, k + 12, Blocks.brick_block, 0);
		this.setBlock(world, i + 15, j + 4, k + 13, Blocks.brick_block, 0);
		this.setBlock(world, i + 15, j + 4, k + 14, Blocks.brick_block, 0);
		this.setBlock(world, i + 15, j + 4, k + 15, Blocks.brick_block, 0);
		this.setBlock(world, i + 15, j + 5, k + 0, Blocks.brick_block, 0);
		this.setBlock(world, i + 15, j + 5, k + 1, Blocks.iron_bars, 0);
		this.setBlock(world, i + 15, j + 5, k + 2, Blocks.brick_block, 0);
		this.setBlock(world, i + 15, j + 5, k + 3, Blocks.iron_bars, 0);
		this.setBlock(world, i + 15, j + 5, k + 4, Blocks.brick_block, 0);
		this.setBlock(world, i + 15, j + 5, k + 5, Blocks.iron_bars, 0);
		this.setBlock(world, i + 15, j + 5, k + 6, Blocks.brick_block, 0);
		this.setBlock(world, i + 15, j + 5, k + 7, Blocks.iron_bars, 0);
		this.setBlock(world, i + 15, j + 5, k + 8, Blocks.iron_bars, 0);
		this.setBlock(world, i + 15, j + 5, k + 9, Blocks.brick_block, 0);
		this.setBlock(world, i + 15, j + 5, k + 10, Blocks.iron_bars, 0);
		this.setBlock(world, i + 15, j + 5, k + 11, Blocks.brick_block, 0);
		this.setBlock(world, i + 15, j + 5, k + 12, Blocks.iron_bars, 0);
		this.setBlock(world, i + 15, j + 5, k + 13, Blocks.brick_block, 0);
		this.setBlock(world, i + 15, j + 5, k + 14, Blocks.iron_bars, 0);
		this.setBlock(world, i + 15, j + 5, k + 15, Blocks.brick_block, 0);
		this.setBlock(world, i + 0, j + 0, k + 0, Blocks.stained_hardened_clay, 0);
		this.setBlock(world, i + 0, j + 0, k + 1, Blocks.stained_hardened_clay, 0);
		this.setBlock(world, i + 0, j + 0, k + 2, Blocks.stained_hardened_clay, 0);
		this.setBlock(world, i + 0, j + 0, k + 3, Blocks.stained_hardened_clay, 0);
		this.setBlock(world, i + 0, j + 0, k + 4, Blocks.stained_hardened_clay, 0);
		this.setBlock(world, i + 0, j + 0, k + 5, Blocks.stained_hardened_clay, 0);
		this.setBlock(world, i + 0, j + 0, k + 6, Blocks.stained_hardened_clay, 0);
		this.setBlock(world, i + 0, j + 0, k + 9, Blocks.stained_hardened_clay, 0);
		this.setBlock(world, i + 0, j + 0, k + 10, Blocks.stained_hardened_clay, 0);
		this.setBlock(world, i + 0, j + 0, k + 11, Blocks.stained_hardened_clay, 0);
		this.setBlock(world, i + 0, j + 0, k + 12, Blocks.stained_hardened_clay, 0);
		this.setBlock(world, i + 0, j + 0, k + 13, Blocks.stained_hardened_clay, 0);
		this.setBlock(world, i + 0, j + 0, k + 14, Blocks.stained_hardened_clay, 0);
		this.setBlock(world, i + 0, j + 0, k + 15, Blocks.stained_hardened_clay, 0);
		this.setBlock(world, i + 1, j + 0, k + 0, Blocks.stained_hardened_clay, 0);
		this.setBlock(world, i + 1, j + 0, k + 1, Blocks.stained_hardened_clay, 0);
		this.setBlock(world, i + 1, j + 0, k + 2, Blocks.stained_hardened_clay, 0);
		this.setBlock(world, i + 1, j + 0, k + 3, Blocks.stained_hardened_clay, 0);
		this.setBlock(world, i + 1, j + 0, k + 4, Blocks.stained_hardened_clay, 0);
		this.setBlock(world, i + 1, j + 0, k + 5, Blocks.stained_hardened_clay, 0);
		this.setBlock(world, i + 1, j + 0, k + 6, Blocks.stained_hardened_clay, 0);
		this.setBlock(world, i + 1, j + 0, k + 9, Blocks.stained_hardened_clay, 0);
		this.setBlock(world, i + 1, j + 0, k + 10, Blocks.stained_hardened_clay, 0);
		this.setBlock(world, i + 1, j + 0, k + 11, Blocks.stained_hardened_clay, 0);
		this.setBlock(world, i + 1, j + 0, k + 12, Blocks.stained_hardened_clay, 0);
		this.setBlock(world, i + 1, j + 0, k + 13, Blocks.stained_hardened_clay, 0);
		this.setBlock(world, i + 1, j + 0, k + 14, Blocks.stained_hardened_clay, 0);
		this.setBlock(world, i + 1, j + 0, k + 15, Blocks.stained_hardened_clay, 0);
		this.setBlock(world, i + 2, j + 0, k + 0, Blocks.stained_hardened_clay, 0);
		this.setBlock(world, i + 2, j + 0, k + 15, Blocks.stained_hardened_clay, 0);
		world.setBlockMetadataWithNotify(i + 2, j + 3, k + 1, 1, 2);
		world.setBlockMetadataWithNotify(i + 2, j + 3, k + 14, 1, 2);
		this.setBlock(world, i + 3, j + 0, k + 0, Blocks.stained_hardened_clay, 0);
		this.setBlock(world, i + 3, j + 0, k + 15, Blocks.stained_hardened_clay, 0);
		this.setBlock(world, i + 4, j + 0, k + 0, Blocks.stained_hardened_clay, 0);
		this.setBlock(world, i + 4, j + 0, k + 15, Blocks.stained_hardened_clay, 0);
		this.setBlock(world, i + 5, j + 0, k + 0, Blocks.stained_hardened_clay, 0);
		this.setBlock(world, i + 5, j + 0, k + 4, Blocks.stained_hardened_clay, 0);
		this.setBlock(world, i + 5, j + 0, k + 5, Blocks.stained_hardened_clay, 0);
		this.setBlock(world, i + 5, j + 0, k + 6, Blocks.stained_hardened_clay, 0);
		this.setBlock(world, i + 5, j + 0, k + 8, Blocks.stained_hardened_clay, 0);
		this.setBlock(world, i + 5, j + 0, k + 9, Blocks.stained_hardened_clay, 0);
		this.setBlock(world, i + 5, j + 0, k + 10, Blocks.stained_hardened_clay, 0);
		this.setBlock(world, i + 5, j + 0, k + 11, Blocks.stained_hardened_clay, 0);
		this.setBlock(world, i + 5, j + 0, k + 15, Blocks.stained_hardened_clay, 0);
		this.setBlock(world, i + 6, j + 0, k + 0, Blocks.stained_hardened_clay, 0);
		this.setBlock(world, i + 6, j + 0, k + 4, Blocks.stained_hardened_clay, 0);
		this.setBlock(world, i + 6, j + 0, k + 11, Blocks.stained_hardened_clay, 0);
		this.setBlock(world, i + 6, j + 0, k + 15, Blocks.stained_hardened_clay, 0);
		this.setBlock(world, i + 7, j + 0, k + 0, Blocks.stained_hardened_clay, 0);
		this.setBlock(world, i + 7, j + 0, k + 4, Blocks.stained_hardened_clay, 0);
		this.setBlock(world, i + 7, j + 0, k + 11, Blocks.stained_hardened_clay, 0);
		this.setBlock(world, i + 7, j + 0, k + 15, Blocks.stained_hardened_clay, 0);
		this.setBlock(world, i + 8, j + 0, k + 0, Blocks.stained_hardened_clay, 0);
		this.setBlock(world, i + 8, j + 0, k + 4, Blocks.stained_hardened_clay, 0);
		this.setBlock(world, i + 8, j + 0, k + 11, Blocks.stained_hardened_clay, 0);
		this.setBlock(world, i + 8, j + 0, k + 15, Blocks.stained_hardened_clay, 0);
		this.setBlock(world, i + 9, j + 0, k + 0, Blocks.stained_hardened_clay, 0);
		this.setBlock(world, i + 9, j + 0, k + 4, Blocks.stained_hardened_clay, 0);
		this.setBlock(world, i + 9, j + 0, k + 11, Blocks.stained_hardened_clay, 0);
		this.setBlock(world, i + 9, j + 0, k + 15, Blocks.stained_hardened_clay, 0);
		this.setBlock(world, i + 10, j + 0, k + 0, Blocks.stained_hardened_clay, 0);
		this.setBlock(world, i + 10, j + 0, k + 4, Blocks.stained_hardened_clay, 0);
		this.setBlock(world, i + 10, j + 0, k + 11, Blocks.stained_hardened_clay, 0);
		this.setBlock(world, i + 10, j + 0, k + 15, Blocks.stained_hardened_clay, 0);
		this.setBlock(world, i + 11, j + 0, k + 0, Blocks.stained_hardened_clay, 0);
		this.setBlock(world, i + 11, j + 0, k + 4, Blocks.stained_hardened_clay, 0);
		this.setBlock(world, i + 11, j + 0, k + 5, Blocks.stained_hardened_clay, 0);
		this.setBlock(world, i + 11, j + 0, k + 6, Blocks.stained_hardened_clay, 0);
		this.setBlock(world, i + 11, j + 0, k + 7, Blocks.stained_hardened_clay, 0);
		this.setBlock(world, i + 11, j + 0, k + 8, Blocks.stained_hardened_clay, 0);
		this.setBlock(world, i + 11, j + 0, k + 9, Blocks.stained_hardened_clay, 0);
		this.setBlock(world, i + 11, j + 0, k + 10, Blocks.stained_hardened_clay, 0);
		this.setBlock(world, i + 11, j + 0, k + 11, Blocks.stained_hardened_clay, 0);
		this.setBlock(world, i + 11, j + 0, k + 15, Blocks.stained_hardened_clay, 0);
		this.setBlock(world, i + 12, j + 0, k + 0, Blocks.stained_hardened_clay, 0);
		this.setBlock(world, i + 12, j + 0, k + 15, Blocks.stained_hardened_clay, 0);
		this.setBlock(world, i + 13, j + 0, k + 0, Blocks.stained_hardened_clay, 0);
		this.setBlock(world, i + 13, j + 0, k + 15, Blocks.stained_hardened_clay, 0);
		this.setBlock(world, i + 14, j + 0, k + 0, Blocks.stained_hardened_clay, 0);
		this.setBlock(world, i + 14, j + 0, k + 15, Blocks.stained_hardened_clay, 0);
		world.setBlockMetadataWithNotify(i + 14, j + 3, k + 1, 3, 2);
		world.setBlockMetadataWithNotify(i + 14, j + 3, k + 14, 4, 2);
		this.setBlock(world, i + 15, j + 0, k + 0, Blocks.stained_hardened_clay, 0);
		this.setBlock(world, i + 15, j + 0, k + 1, Blocks.stained_hardened_clay, 0);
		this.setBlock(world, i + 15, j + 0, k + 2, Blocks.stained_hardened_clay, 0);
		this.setBlock(world, i + 15, j + 0, k + 3, Blocks.stained_hardened_clay, 0);
		this.setBlock(world, i + 15, j + 0, k + 4, Blocks.stained_hardened_clay, 0);
		this.setBlock(world, i + 15, j + 0, k + 5, Blocks.stained_hardened_clay, 0);
		this.setBlock(world, i + 15, j + 0, k + 6, Blocks.stained_hardened_clay, 0);
		this.setBlock(world, i + 15, j + 0, k + 7, Blocks.stained_hardened_clay, 0);
		this.setBlock(world, i + 15, j + 0, k + 8, Blocks.stained_hardened_clay, 0);
		this.setBlock(world, i + 15, j + 0, k + 9, Blocks.stained_hardened_clay, 0);
		this.setBlock(world, i + 15, j + 0, k + 10, Blocks.stained_hardened_clay, 0);
		this.setBlock(world, i + 15, j + 0, k + 11, Blocks.stained_hardened_clay, 0);
		this.setBlock(world, i + 15, j + 0, k + 12, Blocks.stained_hardened_clay, 0);
		this.setBlock(world, i + 15, j + 0, k + 13, Blocks.stained_hardened_clay, 0);
		this.setBlock(world, i + 15, j + 0, k + 14, Blocks.stained_hardened_clay, 0);
		this.setBlock(world, i + 15, j + 0, k + 15, Blocks.stained_hardened_clay, 0);

		return true;
	}


	
}